<?xml version="1.0" encoding="utf-8"?>
<robot name="iiwa14">

  <!-- ===================== Materials ===================== -->
  <material name="gray">
    <color rgba="0.4 0.4 0.4 1"/>
  </material>
  <material name="light_gray">
    <color rgba="0.6 0.6 0.6 1"/>
  </material>
  <material name="black">
    <color rgba="0 0 0 1"/>
  </material>
  <material name="orange">
    <color rgba="1 0.423529 0.0392157 1"/>
  </material>

  <!-- ===================== base ===================== -->
  <link name="base">
    <inertial>
      <origin xyz="-0.1 0 0.07" rpy="0 0 0"/>
      <mass value="5"/>
      <inertia ixx="0.05" ixy="0" ixz="0" iyy="0.06" iyz="0" izz="0.03"/>
    </inertial>
    <visual>
      <origin xyz="0 0 0" rpy="0 0 0"/>
      <geometry>
        <mesh filename="assets/link_0.obj"/>
      </geometry>
      <material name="gray"/>
    </visual>
    <collision>
      <origin xyz="0 0 0.00" rpy="0 0 0"/>
      <geometry><sphere radius="0.07"/></geometry>
    </collision>
  </link>

  <!-- ===================== link1 ===================== -->
  <link name="link1">
    <inertial>
      <origin xyz="0 -0.03 0.12" rpy="0 0 0"/>
      <mass value="5.76"/>
      <inertia ixx="0.0333" ixy="0" ixz="0" iyy="0.033" iyz="0" izz="0.0123"/>
    </inertial>
    <visual>
      <origin xyz="0 0 0" rpy="0 0 0"/>
      <geometry>
        <mesh filename="assets/link_1.obj"/>
      </geometry>
      <material name="gray"/>
    </visual>
    <collision>
      <origin xyz="0 0 -0.0005" rpy="0 0 0"/>
      <geometry><sphere radius="0.08"/></geometry>
    </collision>
    <collision>
      <origin xyz="0.01 -0.025 0.0425" rpy="0 0 0"/>
      <geometry><sphere radius="0.075"/></geometry>
    </collision>
    <collision>
      <origin xyz="-0.01 -0.025 0.0425" rpy="0 0 0"/>
      <geometry><sphere radius="0.075"/></geometry>
    </collision>
    <collision>
      <origin xyz="0.01 -0.045 0.1025" rpy="0 0 0"/>
      <geometry><sphere radius="0.07"/></geometry>
    </collision>
    <collision>
      <origin xyz="-0.01 -0.045 0.1025" rpy="0 0 0"/>
      <geometry><sphere radius="0.07"/></geometry>
    </collision>
  </link>

  <joint name="joint1" type="revolute">
    <origin xyz="0 0 0.1575" rpy="0 0 0"/>
    <parent link="base"/>
    <child link="link1"/>
    <axis xyz="0 0 1"/>
    <limit lower="-2.96706" upper="2.96706" effort="320" velocity="1.4835"/>
  </joint>

  <!-- ===================== link2 ===================== -->
  <link name="link2">
    <inertial>
      <origin xyz="0.0003 0.059 0.042" rpy="1.5708 0 3.14159"/>
      <mass value="6.35"/>
      <inertia ixx="0.0305" ixy="0" ixz="0" iyy="0.0304" iyz="0" izz="0.011"/>
    </inertial>
    <visual>
      <origin xyz="0 0 0" rpy="0 0 0"/>
      <geometry>
        <mesh filename="assets/link_2_orange.obj"/>
      </geometry>
      <material name="orange"/>
    </visual>
    <visual>
      <origin xyz="0 0 0" rpy="0 0 0"/>
      <geometry>
        <mesh filename="assets/link_2_grey.obj"/>
      </geometry>
      <material name="gray"/>
    </visual>
    <collision>
      <origin xyz="0 0 -0.01" rpy="0 0 0"/>
      <geometry><sphere radius="0.095"/></geometry>
    </collision>
    <collision>
      <origin xyz="0 0 0.045" rpy="0 0 0"/>
      <geometry><sphere radius="0.09"/></geometry>
    </collision>
    <collision>
      <origin xyz="-0.01 0.04 0.054" rpy="0 0 0"/>
      <geometry><sphere radius="0.07"/></geometry>
    </collision>
    <collision>
      <origin xyz="-0.01 0.09 0.04" rpy="0 0 0"/>
      <geometry><sphere radius="0.065"/></geometry>
    </collision>
    <collision>
      <origin xyz="-0.01 0.13 0.02" rpy="0 0 0"/>
      <geometry><sphere radius="0.065"/></geometry>
    </collision>
    <collision>
      <origin xyz="0.01 0.04 0.054" rpy="0 0 0"/>
      <geometry><sphere radius="0.07"/></geometry>
    </collision>
    <collision>
      <origin xyz="0.01 0.09 0.04" rpy="0 0 0"/>
      <geometry><sphere radius="0.065"/></geometry>
    </collision>
    <collision>
      <origin xyz="0.01 0.13 0.02" rpy="0 0 0"/>
      <geometry><sphere radius="0.065"/></geometry>
    </collision>
    <collision>
      <origin xyz="0 0.18 0" rpy="0 0 0"/>
      <geometry><sphere radius="0.075"/></geometry>
    </collision>
  </link>

  <joint name="joint2" type="revolute">
    <origin xyz="0 0 0.2025" rpy="1.5708 0 3.14159"/>
    <parent link="link1"/>
    <child link="link2"/>
    <axis xyz="0 0 1"/>
    <limit lower="-2.0944" upper="2.0944" effort="320" velocity="1.4835"/>
  </joint>

  <!-- ===================== link3 ===================== -->
  <link name="link3">
    <inertial>
      <origin xyz="0 0.03 0.13" rpy="0 0 0"/>
      <mass value="3.5"/>
      <inertia ixx="0.025" ixy="0" ixz="0" iyy="0.0238" iyz="0" izz="0.0076"/>
    </inertial>
    <visual>
      <origin xyz="0 0 0" rpy="0 0 0"/>
      <geometry>
        <mesh filename="assets/link_3.obj"/>
      </geometry>
      <material name="gray"/>
    </visual>
    <visual>
      <origin xyz="0 0 0" rpy="0 0 0"/>
      <geometry>
        <mesh filename="assets/band.obj"/>
      </geometry>
      <material name="light_gray"/>
    </visual>
    <visual>
      <origin xyz="0 0 0" rpy="0 0 0"/>
      <geometry>
        <mesh filename="assets/kuka.obj"/>
      </geometry>
      <material name="black"/>
    </visual>
    <collision>
      <origin xyz="0 0 0.0355" rpy="0 0 0"/>
      <geometry><sphere radius="0.075"/></geometry>
    </collision>
    <collision>
      <origin xyz="0.01 0.023 0.0855" rpy="0 0 0"/>
      <geometry><sphere radius="0.06"/></geometry>
    </collision>
    <collision>
      <origin xyz="0.01 0.048 0.1255" rpy="0 0 0"/>
      <geometry><sphere radius="0.055"/></geometry>
    </collision>
    <collision>
      <origin xyz="0.01 0.056 0.1755" rpy="0 0 0"/>
      <geometry><sphere radius="0.06"/></geometry>
    </collision>
    <collision>
      <origin xyz="-0.01 0.023 0.0855" rpy="0 0 0"/>
      <geometry><sphere radius="0.06"/></geometry>
    </collision>
    <collision>
      <origin xyz="-0.01 0.048 0.1255" rpy="0 0 0"/>
      <geometry><sphere radius="0.055"/></geometry>
    </collision>
    <collision>
      <origin xyz="-0.01 0.056 0.1755" rpy="0 0 0"/>
      <geometry><sphere radius="0.06"/></geometry>
    </collision>
    <collision>
      <origin xyz="0 0.045 0.2155" rpy="0 0 0"/>
      <geometry><sphere radius="0.075"/></geometry>
    </collision>
    <collision>
      <origin xyz="0 0 0.2155" rpy="0 0 0"/>
      <geometry><sphere radius="0.075"/></geometry>
    </collision>
  </link>

  <joint name="joint3" type="revolute">
    <origin xyz="0 0.2045 0" rpy="1.5708 0 3.14159"/>
    <parent link="link2"/>
    <child link="link3"/>
    <axis xyz="0 0 1"/>
    <limit lower="-2.96706" upper="2.96706" effort="176" velocity="1.7453"/>
  </joint>

  <!-- ===================== link4 ===================== -->
  <link name="link4">
    <inertial>
      <origin xyz="0 0.067 0.034" rpy="1.5708 0 0"/>
      <mass value="3.5"/>
      <inertia ixx="0.017" ixy="0" ixz="0" iyy="0.0164" iyz="0" izz="0.006"/>
    </inertial>
    <visual>
      <origin xyz="0 0 0" rpy="0 0 0"/>
      <geometry>
        <mesh filename="assets/link_4_orange.obj"/>
      </geometry>
      <material name="orange"/>
    </visual>
    <visual>
      <origin xyz="0 0 0" rpy="0 0 0"/>
      <geometry>
        <mesh filename="assets/link_4_grey.obj"/>
      </geometry>
      <material name="gray"/>
    </visual>
    <collision>
      <origin xyz="0 0.01 0.046" rpy="0 0 0"/>
      <geometry><sphere radius="0.078"/></geometry>
    </collision>
    <collision>
      <origin xyz="0.01 0.06 0.052" rpy="0 0 0"/>
      <geometry><sphere radius="0.06"/></geometry>
    </collision>
    <collision>
      <origin xyz="0.01 0.12 0.034" rpy="0 0 0"/>
      <geometry><sphere radius="0.065"/></geometry>
    </collision>
    <collision>
      <origin xyz="-0.01 0.06 0.052" rpy="0 0 0"/>
      <geometry><sphere radius="0.06"/></geometry>
    </collision>
    <collision>
      <origin xyz="-0.01 0.12 0.034" rpy="0 0 0"/>
      <geometry><sphere radius="0.065"/></geometry>
    </collision>
    <collision>
      <origin xyz="0 0.184 0" rpy="0 0 0"/>
      <geometry><sphere radius="0.075"/></geometry>
    </collision>
  </link>

  <joint name="joint4" type="revolute">
    <origin xyz="0 0 0.2155" rpy="1.5708 0 0"/>
    <parent link="link3"/>
    <child link="link4"/>
    <axis xyz="0 0 1"/>
    <limit lower="-2.0944" upper="2.0944" effort="176" velocity="1.3090"/>
  </joint>

  <!-- ===================== link5 ===================== -->
  <link name="link5">
    <inertial>
      <origin xyz="0.0001 0.021 0.076" rpy="0 0 0"/>
      <mass value="3.5"/>
      <inertia ixx="0.01" ixy="0" ixz="0" iyy="0.0087" iyz="0" izz="0.00449"/>
    </inertial>
    <visual>
      <origin xyz="0 0 0" rpy="0 0 0"/>
      <geometry>
        <mesh filename="assets/link_5.obj"/>
      </geometry>
      <material name="gray"/>
    </visual>
    <visual>
      <origin xyz="0 0 0" rpy="0 0 0"/>
      <geometry>
        <mesh filename="assets/band.obj"/>
      </geometry>
      <material name="light_gray"/>
    </visual>
    <visual>
      <origin xyz="0 0 0" rpy="0 0 0"/>
      <geometry>
        <mesh filename="assets/kuka.obj"/>
      </geometry>
      <material name="black"/>
    </visual>
    <collision>
      <origin xyz="0 0 0.0335" rpy="0 0 0"/>
      <geometry><sphere radius="0.075"/></geometry>
    </collision>
    <collision>
      <origin xyz="-0.012 0.031 0.0755" rpy="0 0 0"/>
      <geometry><sphere radius="0.05"/></geometry>
    </collision>
    <collision>
      <origin xyz="0.012 0.031 0.0755" rpy="0 0 0"/>
      <geometry><sphere radius="0.05"/></geometry>
    </collision>
    <collision>
      <origin xyz="-0.012 0.06 0.1155" rpy="0 0 0"/>
      <geometry><sphere radius="0.04"/></geometry>
    </collision>
    <collision>
      <origin xyz="0.012 0.06 0.1155" rpy="0 0 0"/>
      <geometry><sphere radius="0.04"/></geometry>
    </collision>
    <collision>
      <origin xyz="-0.01 0.065 0.1655" rpy="0 0 0"/>
      <geometry><sphere radius="0.04"/></geometry>
    </collision>
    <collision>
      <origin xyz="0.01 0.065 0.1655" rpy="0 0 0"/>
      <geometry><sphere radius="0.04"/></geometry>
    </collision>
    <collision>
      <origin xyz="-0.012 0.065 0.1855" rpy="0 0 0"/>
      <geometry><sphere radius="0.035"/></geometry>
    </collision>
    <collision>
      <origin xyz="0.012 0.065 0.1855" rpy="0 0 0"/>
      <geometry><sphere radius="0.035"/></geometry>
    </collision>
  </link>

  <joint name="joint5" type="revolute">
    <origin xyz="0 0.1845 0" rpy="1.5708 0 3.14159"/>
    <parent link="link4"/>
    <child link="link5"/>
    <axis xyz="0 0 1"/>
    <limit lower="-2.96706" upper="2.96706" effort="110" velocity="2.2689"/>
  </joint>

  <!-- ===================== link6 ===================== -->
  <link name="link6">
    <inertial>
      <origin xyz="0 0.0006 0.0004" rpy="1.5708 0 0"/>
      <mass value="1.8"/>
      <inertia ixx="0.0049" ixy="0" ixz="0" iyy="0.0047" iyz="0" izz="0.0036"/>
    </inertial>
    <visual>
      <origin xyz="0 0 0" rpy="0 0 0"/>
      <geometry>
        <mesh filename="assets/link_6_orange.obj"/>
      </geometry>
      <material name="orange"/>
    </visual>
    <visual>
      <origin xyz="0 0 0" rpy="0 0 0"/>
      <geometry>
        <mesh filename="assets/link_6_grey.obj"/>
      </geometry>
      <material name="gray"/>
    </visual>
    <collision>
      <origin xyz="0 0 -0.059" rpy="0 0 0"/>
      <geometry><sphere radius="0.055"/></geometry>
    </collision>
    <collision>
      <origin xyz="0 -0.03 0.011" rpy="0 0 0"/>
      <geometry><sphere radius="0.065"/></geometry>
    </collision>
    <collision>
      <origin xyz="0 0 0" rpy="0 0 0"/>
      <geometry><sphere radius="0.08"/></geometry>
    </collision>
  </link>

  <joint name="joint6" type="revolute">
    <origin xyz="0 0 0.2155" rpy="1.5708 0 0"/>
    <parent link="link5"/>
    <child link="link6"/>
    <axis xyz="0 0 1"/>
    <limit lower="-2.0944" upper="2.0944" effort="40" velocity="2.3562"/>
  </joint>

  <!-- ===================== link7 ===================== -->
  <link name="link7">
    <inertial>
      <origin xyz="0 0 0.02" rpy="0 0 0"/>
      <mass value="1.2"/>
      <inertia ixx="0.001" ixy="0" ixz="0" iyy="0.001" iyz="0" izz="0.001"/>
    </inertial>
    <visual>
      <origin xyz="0 0 0" rpy="0 0 0"/>
      <geometry>
        <mesh filename="assets/link_7.obj"/>
      </geometry>
      <material name="gray"/>
    </visual>
    <collision>
      <origin xyz="0 0 0.001" rpy="0 0 0"/>
      <geometry><sphere radius="0.02"/></geometry>
    </collision>
  </link>

  <joint name="joint7" type="revolute">
    <origin xyz="0 0.081 0" rpy="1.5708 0 3.14159"/>
    <parent link="link6"/>
    <child link="link7"/>
    <axis xyz="0 0 1"/>
    <limit lower="-3.05433" upper="3.05433" effort="40" velocity="2.3562"/>
  </joint>

  <!-- ===================== attachment / tcp ===================== -->
  <!-- MJCF sites "attachment_site" and "tcp" (pos 0 0 0.045 on link7) -->
  <link name="attachment_site"/>
  <joint name="attachment_joint" type="fixed">
    <origin xyz="0 0 0.045" rpy="0 0 0"/>
    <parent link="link7"/>
    <child link="attachment_site"/>
  </joint>

    <link name="iiwa_link_ee"></link>
	<link name="robotiq_arg2f_base_link">
		<inertial>
			<origin rpy="0 0 0" xyz="8.625E-08 -4.6583E-06 0.03145"></origin>
			<mass value="0.22652"></mass>
			<inertia ixx="0.00020005" ixy="-4.2442E-10" ixz="-2.9069E-10" iyy="0.00017832" iyz="-3.4402E-08" izz="0.00013478"></inertia>
		</inertial>
		<visual>
			<origin rpy="0 0 0" xyz="0 0 0"></origin>
			<geometry>
				<mesh filename="robotiq_arg2f_85_base_link.stl" scale="0.001 0.001 0.001"></mesh>
			</geometry>
			<material name="">
				<color rgba="0.1 0.1 0.1 1"></color>
			</material>
		</visual>
		<collision>
			<geometry>
				<sphere radius="0.053503"></sphere>
			</geometry>
			<origin xyz="-1e-06 -1e-06 0.03976211301029474" rpy="0 0 0"></origin>
		</collision>
	</link>
	<link name="left_outer_knuckle">
		<visual>
			<origin rpy="0 0 0" xyz="0 0 0"></origin>
			<geometry>
				<mesh filename="robotiq_arg2f_85_outer_knuckle.stl" scale="0.001 0.001 0.001"></mesh>
			</geometry>
			<material name="">
				<color rgba="0.792156862745098 0.819607843137255 0.933333333333333 1"></color>
			</material>
		</visual>
		<collision>
			<geometry>
				<sphere radius="0.010984"></sphere>
			</geometry>
			<origin xyz="1e-06 0.000614150337219239 0.0019120895633697507" rpy="0 0 0"></origin>
		</collision>
		<collision>
			<geometry>
				<sphere radius="0.012432"></sphere>
			</geometry>
			<origin xyz="0.0 -0.005664849662780761 0.02519308956336975" rpy="0 0 0"></origin>
		</collision>
		<collision>
			<geometry>
				<sphere radius="0.012226"></sphere>
			</geometry>
			<origin xyz="0.0 -0.0011238496627807612 0.030192089563369752" rpy="0 0 0"></origin>
		</collision>
		<collision>
			<geometry>
				<sphere radius="0.01123"></sphere>
			</geometry>
			<origin xyz="0.0 -0.0003988496627807612 0.02566108956336975" rpy="0 0 0"></origin>
		</collision>
		<collision>
			<geometry>
				<sphere radius="0.007303"></sphere>
			</geometry>
			<origin xyz="0.0 0.0018341503372192387 0.01490708956336975" rpy="0 0 0"></origin>
		</collision>
	</link>
	<link name="left_outer_finger">
		<visual>
			<origin rpy="0 0 0" xyz="0 0 0"></origin>
			<geometry>
				<mesh filename="robotiq_arg2f_85_outer_finger.stl" scale="0.001 0.001 0.001"></mesh>
			</geometry>
			<material name="">
				<color rgba="0.1 0.1 0.1 1"></color>
			</material>
		</visual>
		<collision>
			<geometry>
				<sphere radius="0.011497"></sphere>
			</geometry>
			<origin xyz="0.00488 0.0015613899745941162 0.012645469244003296" rpy="0 0 0"></origin>
		</collision>
		<collision>
			<geometry>
				<sphere radius="0.009975"></sphere>
			</geometry>
			<origin xyz="-0.006963 0.0003353899745941161 0.0025874692440032952" rpy="0 0 0"></origin>
		</collision>
		<collision>
			<geometry>
				<sphere radius="0.010015"></sphere>
			</geometry>
			<origin xyz="0.008541 0.005245389974594116 0.04569646924400329" rpy="0 0 0"></origin>
		</collision>
		<collision>
			<geometry>
				<sphere radius="0.009339"></sphere>
			</geometry>
			<origin xyz="-0.008399 0.0060863899745941166 0.0465464692440033" rpy="0 0 0"></origin>
		</collision>
		<collision>
			<geometry>
				<sphere radius="0.012389"></sphere>
			</geometry>
			<origin xyz="-0.0059 0.002357389974594116 0.018191469244003295" rpy="0 0 0"></origin>
		</collision>
		<collision>
			<geometry>
				<sphere radius="0.009002"></sphere>
			</geometry>
			<origin xyz="0.007492 1.1389974594116017e-05 0.00020946924400329706" rpy="0 0 0"></origin>
		</collision>
		<collision>
			<geometry>
				<sphere radius="0.011071"></sphere>
			</geometry>
			<origin xyz="-0.007347 0.005145389974594116 0.035527469244003296" rpy="0 0 0"></origin>
		</collision>
		<collision>
			<geometry>
				<sphere radius="0.012221"></sphere>
			</geometry>
			<origin xyz="0.006071 0.0036073899745941163 0.028692469244003295" rpy="0 0 0"></origin>
		</collision>
	</link>
	<link name="left_inner_finger">
		<visual>
			<origin rpy="0 0 0" xyz="0 0 0"></origin>
			<geometry>
				<mesh filename="robotiq_arg2f_85_inner_finger.stl" scale="0.001 0.001 0.001"></mesh>
			</geometry>
			<material name="">
				<color rgba="0.1 0.1 0.1 1"></color>
			</material>
		</visual>
		<collision>
			<geometry>
				<sphere radius="0.010605"></sphere>
			</geometry>
			<origin xyz="-0.0001333776209228618 -0.00042106541417874337 0.00032326162205500997" rpy="0 0 0"></origin>
		</collision>
		<collision>
			<geometry>
				<sphere radius="0.011577"></sphere>
			</geometry>
			<origin xyz="-0.0005533776209228618 -0.009420065414178743 0.0031652616220550107" rpy="0 0 0"></origin>
		</collision>
		<collision>
			<geometry>
				<sphere radius="0.012473"></sphere>
			</geometry>
			<origin xyz="-0.00017537762092286182 -0.01666706541417874 0.00843226162205501" rpy="0 0 0"></origin>
		</collision>
		<collision>
			<geometry>
				<sphere radius="0.007804"></sphere>
			</geometry>
			<origin xyz="0.0035886223790771382 -0.015428065414178743 0.021855261622055012" rpy="0 0 0"></origin>
		</collision>
		<collision>
			<geometry>
				<sphere radius="0.008723"></sphere>
			</geometry>
			<origin xyz="-0.0041273776209228615 -0.015206065414178743 0.024027261622055013" rpy="0 0 0"></origin>
		</collision>
		<collision>
			<geometry>
				<sphere radius="0.007462"></sphere>
			</geometry>
			<origin xyz="0.0031446223790771383 -0.015192065414178745 0.03323426162205501" rpy="0 0 0"></origin>
		</collision>
		<collision>
			<geometry>
				<sphere radius="0.00765"></sphere>
			</geometry>
			<origin xyz="0.0014236223790771382 -0.015800065414178742 0.04095526162205501" rpy="0 0 0"></origin>
		</collision>
		<collision>
			<geometry>
				<sphere radius="0.008548"></sphere>
			</geometry>
			<origin xyz="-0.003940377620922862 -0.015415065414178742 0.03781926162205501" rpy="0 0 0"></origin>
		</collision>
	</link>
	<link name="left_inner_finger_pad">
		<visual>
			<origin rpy="0 0 0" xyz="0 0 0"></origin>
			<geometry>
				<box size="0.022 0.00635 0.0375"></box>
			</geometry>
			<material name="">
				<color rgba="0.9 0.9 0.9 1"></color>
			</material>
		</visual>
		<collision>
			<geometry>
				<sphere radius="0.010554"></sphere>
			</geometry>
			<origin xyz="-0.003856 0.0 -0.011665" rpy="0 0 0"></origin>
		</collision>
		<collision>
			<geometry>
				<sphere radius="0.010972"></sphere>
			</geometry>
			<origin xyz="0.007289 0.0 -0.00895" rpy="0 0 0"></origin>
		</collision>
		<collision>
			<geometry>
				<sphere radius="0.009151"></sphere>
			</geometry>
			<origin xyz="-0.004375 0.0 0.001145" rpy="0 0 0"></origin>
		</collision>
		<collision>
			<geometry>
				<sphere radius="0.010294"></sphere>
			</geometry>
			<origin xyz="0.006914 0.0 0.009851" rpy="0 0 0"></origin>
		</collision>
		<collision>
			<geometry>
				<sphere radius="0.009632"></sphere>
			</geometry>
			<origin xyz="-0.00422 0.0 0.012748" rpy="0 0 0"></origin>
		</collision>
	</link>
	<link name="left_inner_knuckle">
		<visual>
			<origin rpy="0 0 0" xyz="0 0 0"></origin>
			<geometry>
				<mesh filename="robotiq_arg2f_85_inner_knuckle.stl" scale="0.001 0.001 0.001"></mesh>
			</geometry>
			<material name="">
				<color rgba="0.1 0.1 0.1 1"></color>
			</material>
		</visual>
		<collision>
			<geometry>
				<sphere radius="0.011422"></sphere>
			</geometry>
			<origin xyz="0.01575 0.004236976961135865 0.0022316007404327397" rpy="0 0 0"></origin>
		</collision>
		<collision>
			<geometry>
				<sphere radius="0.009271"></sphere>
			</geometry>
			<origin xyz="0.0145 0.012565976961135865 0.01625060074043274" rpy="0 0 0"></origin>
		</collision>
		<collision>
			<geometry>
				<sphere radius="0.012513"></sphere>
			</geometry>
			<origin xyz="0.009482 0.023362976961135866 0.02738060074043274" rpy="0 0 0"></origin>
		</collision>
		<collision>
			<geometry>
				<sphere radius="0.010628"></sphere>
			</geometry>
			<origin xyz="0.008242 0.03606797696113587 0.04220860074043274" rpy="0 0 0"></origin>
		</collision>
		<collision>
			<geometry>
				<sphere radius="0.01315"></sphere>
			</geometry>
			<origin xyz="-0.008981 0.023662976961135868 0.02784160074043274" rpy="0 0 0"></origin>
		</collision>
		<collision>
			<geometry>
				<sphere radius="0.009999"></sphere>
			</geometry>
			<origin xyz="-0.008288 0.03617997696113587 0.042382600740432735" rpy="0 0 0"></origin>
		</collision>
		<collision>
			<geometry>
				<sphere radius="0.009398"></sphere>
			</geometry>
			<origin xyz="-0.0145 0.014375976961135866 0.01504860074043274" rpy="0 0 0"></origin>
		</collision>
		<collision>
			<geometry>
				<sphere radius="0.011428"></sphere>
			</geometry>
			<origin xyz="-0.01575 0.0018039769611358641 0.00444860074043274" rpy="0 0 0"></origin>
		</collision>
	</link>
	<link name="right_outer_knuckle">
		<visual>
			<origin rpy="0 0 0" xyz="0 0 0"></origin>
			<geometry>
				<mesh filename="robotiq_arg2f_85_outer_knuckle.stl" scale="0.001 0.001 0.001"></mesh>
			</geometry>
			<material name="">
				<color rgba="0.792156862745098 0.819607843137255 0.933333333333333 1"></color>
			</material>
		</visual>
		<collision>
			<geometry>
				<sphere radius="0.010984"></sphere>
			</geometry>
			<origin xyz="1e-06 0.000614150337219239 0.0019120895633697507" rpy="0 0 0"></origin>
		</collision>
		<collision>
			<geometry>
				<sphere radius="0.012432"></sphere>
			</geometry>
			<origin xyz="0.0 -0.005664849662780761 0.02519308956336975" rpy="0 0 0"></origin>
		</collision>
		<collision>
			<geometry>
				<sphere radius="0.012226"></sphere>
			</geometry>
			<origin xyz="0.0 -0.0011238496627807612 0.030192089563369752" rpy="0 0 0"></origin>
		</collision>
		<collision>
			<geometry>
				<sphere radius="0.01123"></sphere>
			</geometry>
			<origin xyz="0.0 -0.0003988496627807612 0.02566108956336975" rpy="0 0 0"></origin>
		</collision>
		<collision>
			<geometry>
				<sphere radius="0.007303"></sphere>
			</geometry>
			<origin xyz="0.0 0.0018341503372192387 0.01490708956336975" rpy="0 0 0"></origin>
		</collision>
	</link>
	<link name="right_outer_finger">
		<visual>
			<origin rpy="0 0 0" xyz="0 0 0"></origin>
			<geometry>
				<mesh filename="robotiq_arg2f_85_outer_finger.stl" scale="0.001 0.001 0.001"></mesh>
			</geometry>
			<material name="">
				<color rgba="0.1 0.1 0.1 1"></color>
			</material>
		</visual>
		<collision>
			<geometry>
				<sphere radius="0.011497"></sphere>
			</geometry>
			<origin xyz="0.00488 0.0015613899745941162 0.012645469244003296" rpy="0 0 0"></origin>
		</collision>
		<collision>
			<geometry>
				<sphere radius="0.009975"></sphere>
			</geometry>
			<origin xyz="-0.006963 0.0003353899745941161 0.0025874692440032952" rpy="0 0 0"></origin>
		</collision>
		<collision>
			<geometry>
				<sphere radius="0.010015"></sphere>
			</geometry>
			<origin xyz="0.008541 0.005245389974594116 0.04569646924400329" rpy="0 0 0"></origin>
		</collision>
		<collision>
			<geometry>
				<sphere radius="0.009339"></sphere>
			</geometry>
			<origin xyz="-0.008399 0.0060863899745941166 0.0465464692440033" rpy="0 0 0"></origin>
		</collision>
		<collision>
			<geometry>
				<sphere radius="0.012389"></sphere>
			</geometry>
			<origin xyz="-0.0059 0.002357389974594116 0.018191469244003295" rpy="0 0 0"></origin>
		</collision>
		<collision>
			<geometry>
				<sphere radius="0.009002"></sphere>
			</geometry>
			<origin xyz="0.007492 1.1389974594116017e-05 0.00020946924400329706" rpy="0 0 0"></origin>
		</collision>
		<collision>
			<geometry>
				<sphere radius="0.011071"></sphere>
			</geometry>
			<origin xyz="-0.007347 0.005145389974594116 0.035527469244003296" rpy="0 0 0"></origin>
		</collision>
		<collision>
			<geometry>
				<sphere radius="0.012221"></sphere>
			</geometry>
			<origin xyz="0.006071 0.0036073899745941163 0.028692469244003295" rpy="0 0 0"></origin>
		</collision>
	</link>
	<link name="right_inner_finger">
		<visual>
			<origin rpy="0 0 0" xyz="0 0 0"></origin>
			<geometry>
				<mesh filename="robotiq_arg2f_85_inner_finger.stl" scale="0.001 0.001 0.001"></mesh>
			</geometry>
			<material name="">
				<color rgba="0.1 0.1 0.1 1"></color>
			</material>
		</visual>
		<collision>
			<geometry>
				<sphere radius="0.010605"></sphere>
			</geometry>
			<origin xyz="-0.0001333776209228618 -0.00042106541417874337 0.00032326162205500997" rpy="0 0 0"></origin>
		</collision>
		<collision>
			<geometry>
				<sphere radius="0.011577"></sphere>
			</geometry>
			<origin xyz="-0.0005533776209228618 -0.009420065414178743 0.0031652616220550107" rpy="0 0 0"></origin>
		</collision>
		<collision>
			<geometry>
				<sphere radius="0.012473"></sphere>
			</geometry>
			<origin xyz="-0.00017537762092286182 -0.01666706541417874 0.00843226162205501" rpy="0 0 0"></origin>
		</collision>
		<collision>
			<geometry>
				<sphere radius="0.007804"></sphere>
			</geometry>
			<origin xyz="0.0035886223790771382 -0.015428065414178743 0.021855261622055012" rpy="0 0 0"></origin>
		</collision>
		<collision>
			<geometry>
				<sphere radius="0.008723"></sphere>
			</geometry>
			<origin xyz="-0.0041273776209228615 -0.015206065414178743 0.024027261622055013" rpy="0 0 0"></origin>
		</collision>
		<collision>
			<geometry>
				<sphere radius="0.007462"></sphere>
			</geometry>
			<origin xyz="0.0031446223790771383 -0.015192065414178745 0.03323426162205501" rpy="0 0 0"></origin>
		</collision>
		<collision>
			<geometry>
				<sphere radius="0.00765"></sphere>
			</geometry>
			<origin xyz="0.0014236223790771382 -0.015800065414178742 0.04095526162205501" rpy="0 0 0"></origin>
		</collision>
		<collision>
			<geometry>
				<sphere radius="0.008548"></sphere>
			</geometry>
			<origin xyz="-0.003940377620922862 -0.015415065414178742 0.03781926162205501" rpy="0 0 0"></origin>
		</collision>
	</link>
	<link name="right_inner_finger_pad">
		<visual>
			<origin rpy="0 0 0" xyz="0 0 0"></origin>
			<geometry>
				<box size="0.022 0.00635 0.0375"></box>
			</geometry>
			<material name="">
				<color rgba="0.9 0.9 0.9 1"></color>
			</material>
		</visual>
		<collision>
			<geometry>
				<sphere radius="0.010554"></sphere>
			</geometry>
			<origin xyz="-0.003856 0.0 -0.011665" rpy="0 0 0"></origin>
		</collision>
		<collision>
			<geometry>
				<sphere radius="0.010972"></sphere>
			</geometry>
			<origin xyz="0.007289 0.0 -0.00895" rpy="0 0 0"></origin>
		</collision>
		<collision>
			<geometry>
				<sphere radius="0.009151"></sphere>
			</geometry>
			<origin xyz="-0.004375 0.0 0.001145" rpy="0 0 0"></origin>
		</collision>
		<collision>
			<geometry>
				<sphere radius="0.010294"></sphere>
			</geometry>
			<origin xyz="0.006914 0.0 0.009851" rpy="0 0 0"></origin>
		</collision>
		<collision>
			<geometry>
				<sphere radius="0.009632"></sphere>
			</geometry>
			<origin xyz="-0.00422 0.0 0.012748" rpy="0 0 0"></origin>
		</collision>
	</link>
	<link name="right_inner_knuckle">
		<visual>
			<origin rpy="0 0 0" xyz="0 0 0"></origin>
			<geometry>
				<mesh filename="robotiq_arg2f_85_inner_knuckle.stl" scale="0.001 0.001 0.001"></mesh>
			</geometry>
			<material name="">
				<color rgba="0.1 0.1 0.1 1"></color>
			</material>
		</visual>
		<collision>
			<geometry>
				<sphere radius="0.011422"></sphere>
			</geometry>
			<origin xyz="0.01575 0.004236976961135865 0.0022316007404327397" rpy="0 0 0"></origin>
		</collision>
		<collision>
			<geometry>
				<sphere radius="0.009271"></sphere>
			</geometry>
			<origin xyz="0.0145 0.012565976961135865 0.01625060074043274" rpy="0 0 0"></origin>
		</collision>
		<collision>
			<geometry>
				<sphere radius="0.012513"></sphere>
			</geometry>
			<origin xyz="0.009482 0.023362976961135866 0.02738060074043274" rpy="0 0 0"></origin>
		</collision>
		<collision>
			<geometry>
				<sphere radius="0.010628"></sphere>
			</geometry>
			<origin xyz="0.008242 0.03606797696113587 0.04220860074043274" rpy="0 0 0"></origin>
		</collision>
		<collision>
			<geometry>
				<sphere radius="0.01315"></sphere>
			</geometry>
			<origin xyz="-0.008981 0.023662976961135868 0.02784160074043274" rpy="0 0 0"></origin>
		</collision>
		<collision>
			<geometry>
				<sphere radius="0.009999"></sphere>
			</geometry>
			<origin xyz="-0.008288 0.03617997696113587 0.042382600740432735" rpy="0 0 0"></origin>
		</collision>
		<collision>
			<geometry>
				<sphere radius="0.009398"></sphere>
			</geometry>
			<origin xyz="-0.0145 0.014375976961135866 0.01504860074043274" rpy="0 0 0"></origin>
		</collision>
		<collision>
			<geometry>
				<sphere radius="0.011428"></sphere>
			</geometry>
			<origin xyz="-0.01575 0.0018039769611358641 0.00444860074043274" rpy="0 0 0"></origin>
		</collision>
	</link>
	<joint name="iiwa_joint_ee" type="fixed">
		<parent link="link7"></parent>
		<child link="iiwa_link_ee"></child>
		<origin rpy="0 0 0" xyz="0 0 0.045"></origin>
	</joint>
	<joint name="iiwa_robotiq_mount" type="fixed">
		<parent link="iiwa_link_ee"></parent>
		<child link="robotiq_arg2f_base_link"></child>
		<origin rpy="0 0 0" xyz="0 0 0"></origin>
	</joint>
	<joint name="finger_joint" type="fixed">
		<origin rpy="0 0 3.141592653589793" xyz="0 -0.0306011 0.054904"></origin>
		<parent link="robotiq_arg2f_base_link"></parent>
		<child link="left_outer_knuckle"></child>
	</joint>
	<joint name="left_outer_finger_joint" type="fixed">
		<origin rpy="0 0 0" xyz="0 0.0315 -0.0041"></origin>
		<parent link="left_outer_knuckle"></parent>
		<child link="left_outer_finger"></child>
	</joint>
	<joint name="left_inner_knuckle_joint" type="fixed">
		<origin rpy="0 0 3.141592653589793" xyz="0 -0.0127 0.06142"></origin>
		<parent link="robotiq_arg2f_base_link"></parent>
		<child link="left_inner_knuckle"></child>
	</joint>
	<joint name="left_inner_finger_joint" type="fixed">
		<origin rpy="0 0 0" xyz="0 0.0061 0.0471"></origin>
		<parent link="left_outer_finger"></parent>
		<child link="left_inner_finger"></child>
	</joint>
	<joint name="left_inner_finger_pad_joint" type="fixed">
		<origin rpy="0 0 0" xyz="0 -0.0220203446692936 0.03242"></origin>
		<parent link="left_inner_finger"></parent>
		<child link="left_inner_finger_pad"></child>
	</joint>
	<joint name="right_outer_knuckle_joint" type="fixed">
		<origin rpy="0 0 0" xyz="0 0.0306011 0.054904"></origin>
		<parent link="robotiq_arg2f_base_link"></parent>
		<child link="right_outer_knuckle"></child>
	</joint>
	<joint name="right_outer_finger_joint" type="fixed">
		<origin rpy="0 0 0" xyz="0 0.0315 -0.0041"></origin>
		<parent link="right_outer_knuckle"></parent>
		<child link="right_outer_finger"></child>
	</joint>
	<joint name="right_inner_knuckle_joint" type="fixed">
		<origin rpy="0 0 0.0" xyz="0 0.0127 0.06142"></origin>
		<parent link="robotiq_arg2f_base_link"></parent>
		<child link="right_inner_knuckle"></child>
	</joint>
	<joint name="right_inner_finger_joint" type="fixed">
		<origin rpy="0 0 0" xyz="0 0.0061 0.0471"></origin>
		<parent link="right_outer_finger"></parent>
		<child link="right_inner_finger"></child>
	</joint>
	<joint name="right_inner_finger_pad_joint" type="fixed">
		<origin rpy="0 0 0" xyz="0 -0.0220203446692936 0.03242"></origin>
		<parent link="right_inner_finger"></parent>
		<child link="right_inner_finger_pad"></child>
	</joint>
</robot>