<mujoco model="iiwa14">
  <compiler angle="radian"/>

  <worldbody>
    <geom size="0.07" rgba="0.4 0.4 0.4 1"/>
    <body name="link1" pos="0 0 0.1575">
      <inertial pos="0 -0.03 0.12" mass="5.76" diaginertia="0.0333 0.033 0.0123"/>
      <joint name="joint1" pos="0 0 0" axis="0 0 1" range="-2.96706 2.96706" actuatorfrcrange="-320 320"/>
      <geom size="0.08" pos="0 0 -0.0005" rgba="0.4 0.4 0.4 1"/>
      <geom size="0.075" pos="0.01 -0.025 0.0425" rgba="0.4 0.4 0.4 1"/>
      <geom size="0.075" pos="-0.01 -0.025 0.0425" rgba="0.4 0.4 0.4 1"/>
      <geom size="0.07" pos="0.01 -0.045 0.1025" rgba="0.4 0.4 0.4 1"/>
      <geom size="0.07" pos="-0.01 -0.045 0.1025" rgba="0.4 0.4 0.4 1"/>
      <body name="link2" pos="0 0 0.2025" quat="9.38184e-07 9.38187e-07 0.707108 0.707105">
        <inertial pos="0.0003 0.059 0.042" mass="6.35" diaginertia="0.0305 0.0304 0.011"/>
        <joint name="joint2" pos="0 0 0" axis="0 0 1" range="-2.0944 2.0944" actuatorfrcrange="-320 320"/>
        <geom size="0.095" pos="0 0 -0.01" rgba="0.4 0.4 0.4 1"/>
        <geom size="0.09" pos="0 0 0.045" rgba="0.4 0.4 0.4 1"/>
        <geom size="0.07" pos="-0.01 0.04 0.054" rgba="0.4 0.4 0.4 1"/>
        <geom size="0.065" pos="-0.01 0.09 0.04" rgba="0.4 0.4 0.4 1"/>
        <geom size="0.065" pos="-0.01 0.13 0.02" rgba="0.4 0.4 0.4 1"/>
        <geom size="0.07" pos="0.01 0.04 0.054" rgba="0.4 0.4 0.4 1"/>
        <geom size="0.065" pos="0.01 0.09 0.04" rgba="0.4 0.4 0.4 1"/>
        <geom size="0.065" pos="0.01 0.13 0.02" rgba="0.4 0.4 0.4 1"/>
        <geom size="0.075" pos="0 0.18 0" rgba="0.4 0.4 0.4 1"/>
        <body name="link3" pos="0 0.2045 0" quat="9.38184e-07 9.38187e-07 0.707108 0.707105">
          <inertial pos="0 0.03 0.13" mass="3.5" diaginertia="0.025 0.0238 0.0076"/>
          <joint name="joint3" pos="0 0 0" axis="0 0 1" range="-2.96706 2.96706" actuatorfrcrange="-176 176"/>
          <geom size="0.075" pos="0 0 0.0355" rgba="0 0 0 1"/>
          <geom size="0.06" pos="0.01 0.023 0.0855" rgba="0 0 0 1"/>
          <geom size="0.055" pos="0.01 0.048 0.1255" rgba="0 0 0 1"/>
          <geom size="0.06" pos="0.01 0.056 0.1755" rgba="0 0 0 1"/>
          <geom size="0.06" pos="-0.01 0.023 0.0855" rgba="0 0 0 1"/>
          <geom size="0.055" pos="-0.01 0.048 0.1255" rgba="0 0 0 1"/>
          <geom size="0.06" pos="-0.01 0.056 0.1755" rgba="0 0 0 1"/>
          <geom size="0.075" pos="0 0.045 0.2155" rgba="0 0 0 1"/>
          <geom size="0.075" pos="0 0 0.2155" rgba="0 0 0 1"/>
          <body name="link4" pos="0 0 0.2155" quat="0.707105 0.707108 0 0">
            <inertial pos="0 0.067 0.034" mass="3.5" diaginertia="0.017 0.0164 0.006"/>
            <joint name="joint4" pos="0 0 0" axis="0 0 1" range="-2.0944 2.0944" actuatorfrcrange="-176 176"/>
            <geom size="0.078" pos="0 0.01 0.046" rgba="0.4 0.4 0.4 1"/>
            <geom size="0.06" pos="0.01 0.06 0.052" rgba="0.4 0.4 0.4 1"/>
            <geom size="0.065" pos="0.01 0.12 0.034" rgba="0.4 0.4 0.4 1"/>
            <geom size="0.06" pos="-0.01 0.06 0.052" rgba="0.4 0.4 0.4 1"/>
            <geom size="0.065" pos="-0.01 0.12 0.034" rgba="0.4 0.4 0.4 1"/>
            <geom size="0.075" pos="0 0.184 0" rgba="0.4 0.4 0.4 1"/>
            <body name="link5" pos="0 0.1845 0" quat="9.38184e-07 9.38187e-07 0.707108 0.707105">
              <inertial pos="0.0001 0.021 0.076" mass="3.5" diaginertia="0.01 0.0087 0.00449"/>
              <joint name="joint5" pos="0 0 0" axis="0 0 1" range="-2.96706 2.96706" actuatorfrcrange="-110 110"/>
              <geom size="0.075" pos="0 0 0.0335" rgba="0 0 0 1"/>
              <geom size="0.05" pos="-0.012 0.031 0.0755" rgba="0 0 0 1"/>
              <geom size="0.05" pos="0.012 0.031 0.0755" rgba="0 0 0 1"/>
              <geom size="0.04" pos="-0.012 0.06 0.1155" rgba="0 0 0 1"/>
              <geom size="0.04" pos="0.012 0.06 0.1155" rgba="0 0 0 1"/>
              <geom size="0.04" pos="-0.01 0.065 0.1655" rgba="0 0 0 1"/>
              <geom size="0.04" pos="0.01 0.065 0.1655" rgba="0 0 0 1"/>
              <geom size="0.035" pos="-0.012 0.065 0.1855" rgba="0 0 0 1"/>
              <geom size="0.035" pos="0.012 0.065 0.1855" rgba="0 0 0 1"/>
              <body name="link6" pos="0 0 0.2155" quat="0.707105 0.707108 0 0">
                <inertial pos="0 0.0006 0.0004" mass="1.8" diaginertia="0.0049 0.0047 0.0036"/>
                <joint name="joint6" pos="0 0 0" axis="0 0 1" range="-2.0944 2.0944" actuatorfrcrange="-40 40"/>
                <geom size="0.055" pos="0 0 -0.059" rgba="0.4 0.4 0.4 1"/>
                <geom size="0.065" pos="0 -0.03 0.011" rgba="0.4 0.4 0.4 1"/>
                <geom size="0.08" rgba="0.4 0.4 0.4 1"/>
                <body name="link7" pos="0 0.081 0" quat="9.38184e-07 9.38187e-07 0.707108 0.707105">
                  <inertial pos="-0.000205927 0.00317812 0.0480698" quat="0.998577 -0.0531077 -0.00488539 -0.000413108" mass="1.76687" diaginertia="0.00601623 0.00526692 0.00279039"/>
                  <joint name="joint7" pos="0 0 0" axis="0 0 1" range="-3.05433 3.05433" actuatorfrcrange="-40 40"/>
                  <geom size="0.02" pos="0 0 0.001" rgba="0.4 0.4 0.4 1"/>
                  <geom size="0.053503" pos="-1e-06 -1e-06 0.0847621" rgba="0.1 0.1 0.1 1"/>
                  <geom size="0.010984" pos="-1e-06 -0.0312153 0.101816" quat="0 0 0 1" rgba="0.792157 0.819608 0.933333 1"/>
                  <geom size="0.012432" pos="0 -0.0249363 0.125097" quat="0 0 0 1" rgba="0.792157 0.819608 0.933333 1"/>
                  <geom size="0.012226" pos="0 -0.0294773 0.130096" quat="0 0 0 1" rgba="0.792157 0.819608 0.933333 1"/>
                  <geom size="0.01123" pos="0 -0.0302023 0.125565" quat="0 0 0 1" rgba="0.792157 0.819608 0.933333 1"/>
                  <geom size="0.007303" pos="0 -0.0324353 0.114811" quat="0 0 0 1" rgba="0.792157 0.819608 0.933333 1"/>
                  <geom size="0.011497" pos="-0.00488 -0.0636625 0.108449" quat="0 0 0 1" rgba="0.1 0.1 0.1 1"/>
                  <geom size="0.009975" pos="0.006963 -0.0624365 0.0983915" quat="0 0 0 1" rgba="0.1 0.1 0.1 1"/>
                  <geom size="0.010015" pos="-0.008541 -0.0673465 0.1415" quat="0 0 0 1" rgba="0.1 0.1 0.1 1"/>
                  <geom size="0.009339" pos="0.008399 -0.0681875 0.14235" quat="0 0 0 1" rgba="0.1 0.1 0.1 1"/>
                  <geom size="0.012389" pos="0.0059 -0.0644585 0.113995" quat="0 0 0 1" rgba="0.1 0.1 0.1 1"/>
                  <geom size="0.009002" pos="-0.007492 -0.0621125 0.0960135" quat="0 0 0 1" rgba="0.1 0.1 0.1 1"/>
                  <geom size="0.011071" pos="0.007347 -0.0672465 0.131331" quat="0 0 0 1" rgba="0.1 0.1 0.1 1"/>
                  <geom size="0.012221" pos="-0.006071 -0.0657085 0.124496" quat="0 0 0 1" rgba="0.1 0.1 0.1 1"/>
                  <geom size="0.010605" pos="0.000133378 -0.06778 0.143227" quat="0 0 0 1" rgba="0.1 0.1 0.1 1"/>
                  <geom size="0.011577" pos="0.000553378 -0.058781 0.146069" quat="0 0 0 1" rgba="0.1 0.1 0.1 1"/>
                  <geom size="0.012473" pos="0.000175378 -0.051534 0.151336" quat="0 0 0 1" rgba="0.1 0.1 0.1 1"/>
                  <geom size="0.007804" pos="-0.00358862 -0.052773 0.164759" quat="0 0 0 1" rgba="0.1 0.1 0.1 1"/>
                  <geom size="0.008723" pos="0.00412738 -0.052995 0.166931" quat="0 0 0 1" rgba="0.1 0.1 0.1 1"/>
                  <geom size="0.007462" pos="-0.00314462 -0.053009 0.176138" quat="0 0 0 1" rgba="0.1 0.1 0.1 1"/>
                  <geom size="0.00765" pos="-0.00142362 -0.052401 0.183859" quat="0 0 0 1" rgba="0.1 0.1 0.1 1"/>
                  <geom size="0.008548" pos="0.00394038 -0.052786 0.180723" quat="0 0 0 1" rgba="0.1 0.1 0.1 1"/>
                  <geom size="0.010554" pos="0.003856 -0.0461808 0.163659" quat="0 0 0 1" rgba="0.9 0.9 0.9 1"/>
                  <geom size="0.010972" pos="-0.007289 -0.0461808 0.166374" quat="0 0 0 1" rgba="0.9 0.9 0.9 1"/>
                  <geom size="0.009151" pos="0.004375 -0.0461808 0.176469" quat="0 0 0 1" rgba="0.9 0.9 0.9 1"/>
                  <geom size="0.010294" pos="-0.006914 -0.0461808 0.185175" quat="0 0 0 1" rgba="0.9 0.9 0.9 1"/>
                  <geom size="0.009632" pos="0.00422 -0.0461808 0.188072" quat="0 0 0 1" rgba="0.9 0.9 0.9 1"/>
                  <geom size="0.011422" pos="-0.01575 -0.016937 0.108652" quat="0 0 0 1" rgba="0.1 0.1 0.1 1"/>
                  <geom size="0.009271" pos="-0.0145 -0.025266 0.122671" quat="0 0 0 1" rgba="0.1 0.1 0.1 1"/>
                  <geom size="0.012513" pos="-0.009482 -0.036063 0.133801" quat="0 0 0 1" rgba="0.1 0.1 0.1 1"/>
                  <geom size="0.010628" pos="-0.008242 -0.048768 0.148629" quat="0 0 0 1" rgba="0.1 0.1 0.1 1"/>
                  <geom size="0.01315" pos="0.008981 -0.036363 0.134262" quat="0 0 0 1" rgba="0.1 0.1 0.1 1"/>
                  <geom size="0.009999" pos="0.008288 -0.04888 0.148803" quat="0 0 0 1" rgba="0.1 0.1 0.1 1"/>
                  <geom size="0.009398" pos="0.0145 -0.027076 0.121469" quat="0 0 0 1" rgba="0.1 0.1 0.1 1"/>
                  <geom size="0.011428" pos="0.01575 -0.014504 0.110869" quat="0 0 0 1" rgba="0.1 0.1 0.1 1"/>
                  <geom size="0.010984" pos="1e-06 0.0312153 0.101816" rgba="0.792157 0.819608 0.933333 1"/>
                  <geom size="0.012432" pos="0 0.0249363 0.125097" rgba="0.792157 0.819608 0.933333 1"/>
                  <geom size="0.012226" pos="0 0.0294773 0.130096" rgba="0.792157 0.819608 0.933333 1"/>
                  <geom size="0.01123" pos="0 0.0302023 0.125565" rgba="0.792157 0.819608 0.933333 1"/>
                  <geom size="0.007303" pos="0 0.0324353 0.114811" rgba="0.792157 0.819608 0.933333 1"/>
                  <geom size="0.011497" pos="0.00488 0.0636625 0.108449" rgba="0.1 0.1 0.1 1"/>
                  <geom size="0.009975" pos="-0.006963 0.0624365 0.0983915" rgba="0.1 0.1 0.1 1"/>
                  <geom size="0.010015" pos="0.008541 0.0673465 0.1415" rgba="0.1 0.1 0.1 1"/>
                  <geom size="0.009339" pos="-0.008399 0.0681875 0.14235" rgba="0.1 0.1 0.1 1"/>
                  <geom size="0.012389" pos="-0.0059 0.0644585 0.113995" rgba="0.1 0.1 0.1 1"/>
                  <geom size="0.009002" pos="0.007492 0.0621125 0.0960135" rgba="0.1 0.1 0.1 1"/>
                  <geom size="0.011071" pos="-0.007347 0.0672465 0.131331" rgba="0.1 0.1 0.1 1"/>
                  <geom size="0.012221" pos="0.006071 0.0657085 0.124496" rgba="0.1 0.1 0.1 1"/>
                  <geom size="0.010605" pos="-0.000133378 0.06778 0.143227" rgba="0.1 0.1 0.1 1"/>
                  <geom size="0.011577" pos="-0.000553378 0.058781 0.146069" rgba="0.1 0.1 0.1 1"/>
                  <geom size="0.012473" pos="-0.000175378 0.051534 0.151336" rgba="0.1 0.1 0.1 1"/>
                  <geom size="0.007804" pos="0.00358862 0.052773 0.164759" rgba="0.1 0.1 0.1 1"/>
                  <geom size="0.008723" pos="-0.00412738 0.052995 0.166931" rgba="0.1 0.1 0.1 1"/>
                  <geom size="0.007462" pos="0.00314462 0.053009 0.176138" rgba="0.1 0.1 0.1 1"/>
                  <geom size="0.00765" pos="0.00142362 0.052401 0.183859" rgba="0.1 0.1 0.1 1"/>
                  <geom size="0.008548" pos="-0.00394038 0.052786 0.180723" rgba="0.1 0.1 0.1 1"/>
                  <geom size="0.010554" pos="-0.003856 0.0461808 0.163659" rgba="0.9 0.9 0.9 1"/>
                  <geom size="0.010972" pos="0.007289 0.0461808 0.166374" rgba="0.9 0.9 0.9 1"/>
                  <geom size="0.009151" pos="-0.004375 0.0461808 0.176469" rgba="0.9 0.9 0.9 1"/>
                  <geom size="0.010294" pos="0.006914 0.0461808 0.185175" rgba="0.9 0.9 0.9 1"/>
                  <geom size="0.009632" pos="-0.00422 0.0461808 0.188072" rgba="0.9 0.9 0.9 1"/>
                  <geom size="0.011422" pos="0.01575 0.016937 0.108652" rgba="0.1 0.1 0.1 1"/>
                  <geom size="0.009271" pos="0.0145 0.025266 0.122671" rgba="0.1 0.1 0.1 1"/>
                  <geom size="0.012513" pos="0.009482 0.036063 0.133801" rgba="0.1 0.1 0.1 1"/>
                  <geom size="0.010628" pos="0.008242 0.048768 0.148629" rgba="0.1 0.1 0.1 1"/>
                  <geom size="0.01315" pos="-0.008981 0.036363 0.134262" rgba="0.1 0.1 0.1 1"/>
                  <geom size="0.009999" pos="-0.008288 0.04888 0.148803" rgba="0.1 0.1 0.1 1"/>
                  <geom size="0.009398" pos="-0.0145 0.027076 0.121469" rgba="0.1 0.1 0.1 1"/>
                  <geom size="0.011428" pos="-0.01575 0.014504 0.110869" rgba="0.1 0.1 0.1 1"/>
                </body>
              </body>
            </body>
          </body>
        </body>
      </body>
    </body>
  </worldbody>
</mujoco>
