<?xml version="1.0" encoding="utf-8"?>
<!-- =================================================================================== -->
<!-- |    This document was autogenerated by xacro from sda10f_1.xacro                 | -->
<!-- |    EDITING THIS FILE BY HAND IS NOT RECOMMENDED                                 | -->
<!-- =================================================================================== -->
<robot name="motoman_sda10f">
  <!-- link list -->
  <link name="torso_base_link">
    <visual>
      <geometry>
        <mesh filename="package://motoman_sda10f_support/meshes/sda10f/visual/base.stl"/>
      </geometry>
      <material name="">
        <color rgba="0.129411764706 0.149019607843 0.749019607843 1.0"/>
      </material>
    </visual>
    <collision>
      <geometry>
        <mesh filename="package://motoman_sda10f_support/meshes/sda10f/collision/base.stl"/>
      </geometry>
    </collision>
  </link>
  <link name="torso_link_b1">
    <visual>
      <origin rpy="0 0 0" xyz="0 0 0"/>
      <geometry>
        <mesh filename="package://motoman_sda10f_support/meshes/sda10f/visual/link_b1.stl"/>
      </geometry>
      <material name="">
        <color rgba="0.99 0.99 0.99 1"/>
      </material>
    </visual>
    <collision>
      <origin rpy="0 0 0" xyz="0 0 0"/>
      <geometry>
        <mesh filename="package://motoman_sda10f_support/meshes/sda10f/collision/link_b1.stl"/>
      </geometry>
    </collision>
  </link>
  <link name="torso_link_b2"/>
  <!-- joint list -->
  <joint name="torso_joint_b1" type="revolute">
    <parent link="torso_base_link"/>
    <child link="torso_link_b1"/>
    <origin rpy="0 0 0" xyz="0 0 0"/>
    <axis xyz="0 0 1"/>
    <limit effort="100" lower="-2.96705972839" upper="2.96705972839" velocity="2.26892802759"/>
  </joint>
  <joint name="torso_joint_b2" type="revolute">
    <parent link="torso_base_link"/>
    <child link="torso_link_b2"/>
    <origin rpy="0 0 0" xyz="0 0 0"/>
    <axis xyz="0 0 1"/>
    <limit effort="100" lower="-2.96705972839" upper="2.96705972839" velocity="2.26892802759"/>
    <mimic joint="torso_joint_b1" multiplier="1" offset="0"/>
  </joint>
  <!-- end of joint list -->
  <link name="arm_left_link_1_s">
    <visual>
      <origin rpy="0 0 0" xyz="0 0 0"/>
      <geometry>
        <mesh filename="package://motoman_sda10f_support/meshes/sda10f/visual/link_s.stl"/>
      </geometry>
      <material name="">
        <color rgba="0.129411764706 0.149019607843 0.749019607843 1.0"/>
      </material>
    </visual>
    <collision>
      <origin rpy="0 0 0" xyz="0 0 0"/>
      <geometry>
        <mesh filename="package://motoman_sda10f_support/meshes/sda10f/collision/link_s.stl"/>
      </geometry>
    </collision>
  </link>
  <link name="arm_left_link_2_l">
    <visual>
      <origin rpy="0 0 0" xyz="0 0 0"/>
      <geometry>
        <mesh filename="package://motoman_sda10f_support/meshes/sda10f/visual/link_l.stl"/>
      </geometry>
      <material name="">
        <color rgba="0.99 0.99 0.99 1"/>
      </material>
    </visual>
    <collision>
      <origin rpy="0 0 0" xyz="0 0 0"/>
      <geometry>
        <mesh filename="package://motoman_sda10f_support/meshes/sda10f/collision/link_l.stl"/>
      </geometry>
    </collision>
  </link>
  <link name="arm_left_link_3_e">
    <visual>
      <origin rpy="0 0 0" xyz="0 0 0"/>
      <geometry>
        <mesh filename="package://motoman_sda10f_support/meshes/sda10f/visual/link_e.stl"/>
      </geometry>
      <material name="">
        <color rgba="0.129411764706 0.149019607843 0.749019607843 1.0"/>
      </material>
    </visual>
    <collision>
      <origin rpy="0 0 0" xyz="0 0 0"/>
      <geometry>
        <mesh filename="package://motoman_sda10f_support/meshes/sda10f/collision/link_e.stl"/>
      </geometry>
    </collision>
  </link>
  <link name="arm_left_link_4_u">
    <visual>
      <origin rpy="0 0 0" xyz="0 0 0"/>
      <geometry>
        <mesh filename="package://motoman_sda10f_support/meshes/sda10f/visual/link_u.stl"/>
      </geometry>
      <material name="">
        <color rgba="0.99 0.99 0.99 1"/>
      </material>
    </visual>
    <collision>
      <origin rpy="0 0 0" xyz="0 0 0"/>
      <geometry>
        <mesh filename="package://motoman_sda10f_support/meshes/sda10f/collision/link_u.stl"/>
      </geometry>
    </collision>
  </link>
  <link name="arm_left_link_5_r">
    <visual>
      <origin rpy="0 0 0" xyz="0 0 0"/>
      <geometry>
        <mesh filename="package://motoman_sda10f_support/meshes/sda10f/visual/link_r.stl"/>
      </geometry>
      <material name="">
        <color rgba="0.129411764706 0.149019607843 0.749019607843 1.0"/>
      </material>
    </visual>
    <collision>
      <origin rpy="0 0 0" xyz="0 0 0"/>
      <geometry>
        <mesh filename="package://motoman_sda10f_support/meshes/sda10f/collision/link_r.stl"/>
      </geometry>
    </collision>
  </link>
  <link name="arm_left_link_6_b">
    <visual>
      <origin rpy="0 0 0" xyz="0 0 0"/>
      <geometry>
        <mesh filename="package://motoman_sda10f_support/meshes/sda10f/visual/link_b.stl"/>
      </geometry>
      <material name="">
        <color rgba="0.99 0.99 0.99 1"/>
      </material>
    </visual>
    <collision>
      <origin rpy="0 0 0" xyz="0 0 0"/>
      <geometry>
        <mesh filename="package://motoman_sda10f_support/meshes/sda10f/collision/link_b.stl"/>
      </geometry>
    </collision>
  </link>
  <link name="arm_left_link_7_t">
    <visual>
      <geometry>
        <mesh filename="package://motoman_sda10f_support/meshes/sda10f/visual/link_t.stl"/>
      </geometry>
      <material name="">
        <color rgba="0.129411764706 0.149019607843 0.749019607843 1.0"/>
      </material>
    </visual>
    <collision>
      <geometry>
        <mesh filename="package://motoman_sda10f_support/meshes/sda10f/collision/link_t.stl"/>
      </geometry>
    </collision>
  </link>
  <link name="arm_left_link_tool0"/>
  <joint name="arm_left_joint_1_s" type="revolute">
    <parent link="torso_link_b1"/>
    <child link="arm_left_link_1_s"/>
    <origin rpy="1.57079632679 0.0 0.0" xyz="0.100 0.265 0.0"/>
    <axis xyz="0 0 -1"/>
    <limit effort="0" lower="-3.14159265359" upper="3.14159265359" velocity="2.96705972839"/>
  </joint>
  <joint name="arm_left_joint_2_l" type="revolute">
    <parent link="arm_left_link_1_s"/>
    <child link="arm_left_link_2_l"/>
    <origin rpy="-1.57079632679 0.0 0.0" xyz="0.0 0.0 0.0"/>
    <axis xyz="0 0 -1"/>
    <limit effort="0" lower="-1.91986217719" upper="1.91986217719" velocity="2.96705972839"/>
  </joint>
  <joint name="arm_left_joint_3_e" type="revolute">
    <parent link="arm_left_link_2_l"/>
    <child link="arm_left_link_3_e"/>
    <origin rpy="1.57079632679 0.0 0.0" xyz="0.0 0.360 0.0"/>
    <axis xyz="0 0 -1"/>
    <limit effort="0" lower="-2.96705972839" upper="2.96705972839" velocity="2.96705972839"/>
  </joint>
  <joint name="arm_left_joint_4_u" type="revolute">
    <parent link="arm_left_link_3_e"/>
    <child link="arm_left_link_4_u"/>
    <origin rpy="-1.57079632679 0.0 0.0" xyz="0.0 0.0 0.0"/>
    <axis xyz="0 0 1"/>
    <limit effort="0" lower="-2.35619449019" upper="2.35619449019" velocity="2.96705972839"/>
  </joint>
  <joint name="arm_left_joint_5_r" type="revolute">
    <parent link="arm_left_link_4_u"/>
    <child link="arm_left_link_5_r"/>
    <origin rpy="1.57079632679 0.0 0.0" xyz="0.0 0.360 0.0"/>
    <axis xyz="0 0 1"/>
    <limit effort="0" lower="-3.14159265359" upper="3.14159265359" velocity="3.49065850399"/>
  </joint>
  <joint name="arm_left_joint_6_b" type="revolute">
    <parent link="arm_left_link_5_r"/>
    <child link="arm_left_link_6_b"/>
    <origin rpy="-1.57079632679 0.0 0.0" xyz="0.0 0.0 0.0"/>
    <axis xyz="0 0 1"/>
    <limit effort="0" lower="-1.91986217719" upper="1.91986217719" velocity="3.49065850399"/>
  </joint>
  <joint name="arm_left_joint_7_t" type="revolute">
    <parent link="arm_left_link_6_b"/>
    <child link="arm_left_link_7_t"/>
    <origin rpy="-1.57079632679 0.0 0.0" xyz="0.0 0.155 0.0"/>
    <axis xyz="0 0 -1"/>
    <limit effort="0" lower="-3.14159265359" upper="3.14159265359" velocity="6.98131700798"/>
  </joint>
  <joint name="arm_left_joint_tool0" type="fixed">
    <parent link="arm_left_link_7_t"/>
    <child link="arm_left_link_tool0"/>
    <origin rpy="0 0 3.14159265359" xyz="0 0 0"/>
  </joint>
  <!-- end of joint list -->
  <link name="arm_right_link_1_s">
    <visual>
      <origin rpy="0 0 0" xyz="0 0 0"/>
      <geometry>
        <mesh filename="package://motoman_sda10f_support/meshes/sda10f/visual/link_s.stl"/>
      </geometry>
      <material name="">
        <color rgba="0.129411764706 0.149019607843 0.749019607843 1.0"/>
      </material>
    </visual>
    <collision>
      <origin rpy="0 0 0" xyz="0 0 0"/>
      <geometry>
        <mesh filename="package://motoman_sda10f_support/meshes/sda10f/collision/link_s.stl"/>
      </geometry>
    </collision>
  </link>
  <link name="arm_right_link_2_l">
    <visual>
      <origin rpy="0 0 0" xyz="0 0 0"/>
      <geometry>
        <mesh filename="package://motoman_sda10f_support/meshes/sda10f/visual/link_l.stl"/>
      </geometry>
      <material name="">
        <color rgba="0.99 0.99 0.99 1"/>
      </material>
    </visual>
    <collision>
      <origin rpy="0 0 0" xyz="0 0 0"/>
      <geometry>
        <mesh filename="package://motoman_sda10f_support/meshes/sda10f/collision/link_l.stl"/>
      </geometry>
    </collision>
  </link>
  <link name="arm_right_link_3_e">
    <visual>
      <origin rpy="0 0 0" xyz="0 0 0"/>
      <geometry>
        <mesh filename="package://motoman_sda10f_support/meshes/sda10f/visual/link_e.stl"/>
      </geometry>
      <material name="">
        <color rgba="0.129411764706 0.149019607843 0.749019607843 1.0"/>
      </material>
    </visual>
    <collision>
      <origin rpy="0 0 0" xyz="0 0 0"/>
      <geometry>
        <mesh filename="package://motoman_sda10f_support/meshes/sda10f/collision/link_e.stl"/>
      </geometry>
    </collision>
  </link>
  <link name="arm_right_link_4_u">
    <visual>
      <origin rpy="0 0 0" xyz="0 0 0"/>
      <geometry>
        <mesh filename="package://motoman_sda10f_support/meshes/sda10f/visual/link_u.stl"/>
      </geometry>
      <material name="">
        <color rgba="0.99 0.99 0.99 1"/>
      </material>
    </visual>
    <collision>
      <origin rpy="0 0 0" xyz="0 0 0"/>
      <geometry>
        <mesh filename="package://motoman_sda10f_support/meshes/sda10f/collision/link_u.stl"/>
      </geometry>
    </collision>
  </link>
  <link name="arm_right_link_5_r">
    <visual>
      <origin rpy="0 0 0" xyz="0 0 0"/>
      <geometry>
        <mesh filename="package://motoman_sda10f_support/meshes/sda10f/visual/link_r.stl"/>
      </geometry>
      <material name="">
        <color rgba="0.129411764706 0.149019607843 0.749019607843 1.0"/>
      </material>
    </visual>
    <collision>
      <origin rpy="0 0 0" xyz="0 0 0"/>
      <geometry>
        <mesh filename="package://motoman_sda10f_support/meshes/sda10f/collision/link_r.stl"/>
      </geometry>
    </collision>
  </link>
  <link name="arm_right_link_6_b">
    <visual>
      <origin rpy="0 0 0" xyz="0 0 0"/>
      <geometry>
        <mesh filename="package://motoman_sda10f_support/meshes/sda10f/visual/link_b.stl"/>
      </geometry>
      <material name="">
        <color rgba="0.99 0.99 0.99 1"/>
      </material>
    </visual>
    <collision>
      <origin rpy="0 0 0" xyz="0 0 0"/>
      <geometry>
        <mesh filename="package://motoman_sda10f_support/meshes/sda10f/collision/link_b.stl"/>
      </geometry>
    </collision>
  </link>
  <link name="arm_right_link_7_t">
    <visual>
      <geometry>
        <mesh filename="package://motoman_sda10f_support/meshes/sda10f/visual/link_t.stl"/>
      </geometry>
      <material name="">
        <color rgba="0.129411764706 0.149019607843 0.749019607843 1.0"/>
      </material>
    </visual>
    <collision>
      <geometry>
        <mesh filename="package://motoman_sda10f_support/meshes/sda10f/collision/link_t.stl"/>
      </geometry>
    </collision>
  </link>
  <link name="arm_right_link_tool0"/>
  <joint name="arm_right_joint_1_s" type="revolute">
    <parent link="torso_link_b1"/>
    <child link="arm_right_link_1_s"/>
    <origin rpy="1.57079632679 0.0 -3.14159265359" xyz="0.100 -0.265 0.0"/>
    <axis xyz="0 0 1"/>
    <limit effort="0" lower="-3.14159265359" upper="3.14159265359" velocity="2.96705972839"/>
  </joint>
  <joint name="arm_right_joint_2_l" type="revolute">
    <parent link="arm_right_link_1_s"/>
    <child link="arm_right_link_2_l"/>
    <origin rpy="-1.57079632679 0.0 0.0" xyz="0.0 0.0 0.0"/>
    <axis xyz="0 0 1"/>
    <limit effort="0" lower="-1.91986217719" upper="1.91986217719" velocity="2.96705972839"/>
  </joint>
  <joint name="arm_right_joint_3_e" type="revolute">
    <parent link="arm_right_link_2_l"/>
    <child link="arm_right_link_3_e"/>
    <origin rpy="1.57079632679 0.0 0.0" xyz="0.0 0.360 0.0"/>
    <axis xyz="0 0 1"/>
    <limit effort="0" lower="-2.96705972839" upper="2.96705972839" velocity="2.96705972839"/>
  </joint>
  <joint name="arm_right_joint_4_u" type="revolute">
    <parent link="arm_right_link_3_e"/>
    <child link="arm_right_link_4_u"/>
    <origin rpy="-1.57079632679 0.0 0.0" xyz="0.0 0.0 0.0"/>
    <axis xyz="0 0 -1"/>
    <limit effort="0" lower="-2.35619449019" upper="2.35619449019" velocity="2.96705972839"/>
  </joint>
  <joint name="arm_right_joint_5_r" type="revolute">
    <parent link="arm_right_link_4_u"/>
    <child link="arm_right_link_5_r"/>
    <origin rpy="1.57079632679 0.0 0.0" xyz="0.0 0.360 0.0"/>
    <axis xyz="0 0 -1"/>
    <limit effort="0" lower="-3.14159265359" upper="3.14159265359" velocity="3.49065850399"/>
  </joint>
  <joint name="arm_right_joint_6_b" type="revolute">
    <parent link="arm_right_link_5_r"/>
    <child link="arm_right_link_6_b"/>
    <origin rpy="-1.57079632679 0.0 0.0" xyz="0.0 0.0 0.0"/>
    <axis xyz="0 0 -1"/>
    <limit effort="0" lower="-1.91986217719" upper="1.91986217719" velocity="3.49065850399"/>
  </joint>
  <joint name="arm_right_joint_7_t" type="revolute">
    <parent link="arm_right_link_6_b"/>
    <child link="arm_right_link_7_t"/>
    <origin rpy="-1.57079632679 0.0 0.0" xyz="0.0 0.155 0.0"/>
    <axis xyz="0 0 1"/>
    <limit effort="0" lower="-3.14159265359" upper="3.14159265359" velocity="6.98131700798"/>
  </joint>
  <joint name="arm_right_joint_tool0" type="fixed">
    <parent link="arm_right_link_7_t"/>
    <child link="arm_right_link_tool0"/>
    <origin rpy="0 0 3.14159265359" xyz="0 0 0"/>
  </joint>
  <!-- end of joint list -->
  <!-- link list -->
  <link name="base_link"/>
  <!-- joint list -->
  <joint name="base_link_torso" type="fixed">
    <parent link="base_link"/>
    <child link="torso_base_link"/>
    <origin rpy="0 0 0" xyz="0 0 1.2"/>
  </joint>
</robot>

