<?xml version="1.0" encoding="utf-8"?>
<robot name="iiwa" xmlns:xacro="http://www.ros.org/wiki/xacro" path="/home/vr-cuongvu/manipcube/collision/iiwa14_with_griper.urdf">
	<material name="Black">
		<color rgba="0.0 0.0 0.0 1.0"></color>
	</material>
	<material name="Blue">
		<color rgba="0.0 0.0 0.8 1.0"></color>
	</material>
	<material name="Green">
		<color rgba="0.0 0.8 0.0 1.0"></color>
	</material>
	<material name="Grey">
		<color rgba="0.4 0.4 0.4 1.0"></color>
	</material>
	<material name="Orange">
		<color rgba="1.0 0.423529411765 0.0392156862745 1.0"></color>
	</material>
	<material name="Brown">
		<color rgba="0.870588235294 0.811764705882 0.764705882353 1.0"></color>
	</material>
	<material name="Red">
		<color rgba="0.8 0.0 0.0 1.0"></color>
	</material>
	<material name="White">
		<color rgba="1.0 1.0 1.0 1.0"></color>
	</material>
	<link name="world"></link>
	<link name="iiwa_link_0">
		<inertial>
			<origin rpy="0 0 0" xyz="-0.1 0 0.07"></origin>
			<mass value="5"></mass>
			<inertia ixx="0.05" ixy="0" ixz="0" iyy="0.06" iyz="0" izz="0.03"></inertia>
		</inertial>
		<visual>
			<origin rpy="0 0 0" xyz="0 0 0"></origin>
			<geometry>
				<mesh filename="link_0.stl"></mesh>
			</geometry>
			<material name="Grey"></material>
		</visual>
		<collision>
			<geometry>
				<sphere radius="0.05"></sphere>
			</geometry>
			<origin xyz="0 0 0.07" rpy="0 0 0"></origin>
		</collision>
		<self_collision_checking>
			<origin rpy="0 0 0" xyz="0 0 0"></origin>
			<geometry>
				<capsule length="0.25" radius="0.15"></capsule>
			</geometry>
		</self_collision_checking>
	</link>
	<link name="iiwa_link_1">
		<inertial>
			<origin rpy="0 0 0" xyz="0 -0.03 0.12"></origin>
			<mass value="4"></mass>
			<inertia ixx="0.1" ixy="0" ixz="0" iyy="0.09" iyz="0" izz="0.02"></inertia>
		</inertial>
		<visual>
			<origin rpy="0 0 0" xyz="0 0 0"></origin>
			<geometry>
				<mesh filename="link_1.stl"></mesh>
			</geometry>
			<material name="Orange"></material>
		</visual>
		<collision>
			<geometry>
				<sphere radius="0.07"></sphere>
			</geometry>
			<origin xyz="0 0 0.04433624530905485" rpy="0 0 0"></origin>
		</collision>

		<!-- <collision>
			<geometry>
				<mesh filename="link_1.stl"></mesh>
			</geometry>
		</collision> -->


		<!-- <collision>
			<geometry>
				<sphere radius="0.111067"></sphere>
			</geometry>
			<origin xyz="0.001106 -0.058825115669727326 0.19394224530905485" rpy="0 0 0"></origin>
		</collision> -->
	</link>
	<link name="iiwa_link_2">
		<inertial>
			<origin rpy="0 0 0" xyz="0.0003 0.059 0.042"></origin>
			<mass value="4"></mass>
			<inertia ixx="0.05" ixy="0" ixz="0" iyy="0.018" iyz="0" izz="0.044"></inertia>
		</inertial>
		<visual>
			<origin rpy="0 0 0" xyz="0 0 0"></origin>
			<geometry>
				<mesh filename="link_2.stl"></mesh>
			</geometry>
			<material name="Orange"></material>
		</visual>
		<!-- <collision>
			<geometry>
				<mesh filename="link_2.stl"></mesh>
			</geometry>
		</collision> -->
		<collision>
			<geometry>
				<sphere radius="0.12"></sphere>
			</geometry>
			<origin xyz="0 0.05 -0" rpy="0 0 0"></origin>
		</collision>
		<!-- <collision>
			<geometry>
				<sphere radius="0.094343"></sphere>
			</geometry>
			<origin xyz="0.0021774437662122337 0.1272096774118195 0.03709771647936554" rpy="0 0 0"></origin>
		</collision>
		<collision>
			<geometry>
				<sphere radius="0.088597"></sphere>
			</geometry>
			<origin xyz="0.0005294437662122336 0.16166567741181948 0.0007457164793655477" rpy="0 0 0"></origin>
		</collision> -->
	</link>
	<link name="iiwa_link_3">
		<inertial>
			<origin rpy="0 0 0" xyz="0 0.03 0.13"></origin>
			<mass value="3"></mass>
			<inertia ixx="0.08" ixy="0" ixz="0" iyy="0.075" iyz="0" izz="0.01"></inertia>
		</inertial>
		<visual>
			<origin rpy="0 0 0" xyz="0 0 0"></origin>
			<geometry>
				<mesh filename="link_3.stl"></mesh>
			</geometry>
			<material name="Orange"></material>
		</visual>
		<collision>
			<geometry>
				<sphere radius="0.12"></sphere>
			</geometry>
			<origin xyz="0 0.0 0.05" rpy="0 0 0"></origin>
		</collision>
		<!-- <collision>
			<geometry>
				<mesh filename="link_3.stl"></mesh>
			</geometry>
		</collision> -->
		<!-- <collision>
			<geometry>
				<sphere radius="0.094513"></sphere>
			</geometry>
			<origin xyz="-0.004060148668283575 0.055049995206667444 0.17516534316468124" rpy="0 0 0"></origin>
		</collision>
		<collision>
			<geometry>
				<sphere radius="0.091499"></sphere>
			</geometry>
			<origin xyz="-0.0016271486682835744 0.053143995206667446 0.22332234316468125" rpy="0 0 0"></origin>
		</collision> -->
	</link>
	<link name="iiwa_link_4">
		<inertial>
			<origin rpy="0 0 0" xyz="0 0.067 0.034"></origin>
			<mass value="2.7"></mass>
			<inertia ixx="0.03" ixy="0" ixz="0" iyy="0.01" iyz="0" izz="0.029"></inertia>
		</inertial>
		<visual>
			<origin rpy="0 0 0" xyz="0 0 0"></origin>
			<geometry>
				<mesh filename="link_4.stl"></mesh>
			</geometry>
			<material name="Orange"></material>
		</visual>
		<!-- <collision>
			<geometry>
				<mesh filename="link_4.stl"></mesh>
			</geometry>
		</collision> -->
		<collision>
			<geometry>
				<sphere radius="0.12"></sphere>
			</geometry>
			<origin xyz="0 0.05 0" rpy="0 0 0"></origin>
		</collision>
		<collision>
			<geometry>
				<sphere radius="0.08"></sphere>
			</geometry>
			<origin xyz="0 0.25 0" rpy="0 0 0"></origin>
		</collision>
		<collision>
			<geometry>
				<sphere radius="0.08"></sphere>
			</geometry>
			<origin xyz="0 0.38 0" rpy="0 0 0"></origin>
		</collision>
		<!-- <collision>
			<geometry>
				<sphere radius="0.100873"></sphere>
			</geometry>
			<origin xyz="0.003023963138047956 0.1360124312493498 0.01263666769684271" rpy="0 0 0"></origin>
		</collision> -->
	</link>
	<link name="iiwa_link_5">
		<inertial>
			<origin rpy="0 0 0" xyz="0.0001 0.021 0.076"></origin>
			<mass value="1.7"></mass>
			<inertia ixx="0.02" ixy="0" ixz="0" iyy="0.018" iyz="0" izz="0.005"></inertia>
		</inertial>
		<visual>
			<origin rpy="0 0 0" xyz="0 0 0"></origin>
			<geometry>
				<mesh filename="link_5.stl"></mesh>
			</geometry>
			<material name="Orange"></material>
		</visual>
		<!-- <collision>
			<geometry>
				<sphere radius="0.08"></sphere>
			</geometry>
			<origin xyz="0 0.0 0.06" rpy="0 0 0"></origin>
		</collision> -->
		<!-- <collision>
			<geometry>
				<sphere radius="0.060316"></sphere>
			</geometry>
			<origin xyz="0.001271918451133753 0.05539640319870423 0.10197422567574664" rpy="0 0 0"></origin>
		</collision>
		<collision>
			<geometry>
				<sphere radius="0.053565"></sphere>
			</geometry>
			<origin xyz="-0.001081081548866247 0.07904740319870424 0.16888122567574665" rpy="0 0 0"></origin>
		</collision>
		<collision>
			<geometry>
				<sphere radius="0.050852"></sphere>
			</geometry>
			<origin xyz="-0.019312081548866246 0.07683040319870424 0.22751122567574664" rpy="0 0 0"></origin>
		</collision>
		<collision>
			<geometry>
				<sphere radius="0.050366"></sphere>
			</geometry>
			<origin xyz="0.02166291845113375 0.07698640319870423 0.22620222567574666" rpy="0 0 0"></origin>
		</collision> -->
		<!-- <collision>
			<geometry>
				<mesh filename="link_5.stl"></mesh>
			</geometry>
		</collision> -->
	</link>
	<link name="iiwa_link_6">
		<inertial>
			<origin rpy="0 0 0" xyz="0 0.0006 0.0004"></origin>
			<mass value="1.8"></mass>
			<inertia ixx="0.005" ixy="0" ixz="0" iyy="0.0036" iyz="0" izz="0.0047"></inertia>
		</inertial>
		<visual>
			<origin rpy="0 0 0" xyz="0 0 0"></origin>
			<geometry>
				<mesh filename="link_6.stl"></mesh>
			</geometry>
			<material name="Orange"></material>
		</visual>
		<!-- <collision>
			<geometry>
				<mesh filename="link_6.stl"></mesh>
			</geometry>
		</collision> -->
<!-- 
		<collision>
			<geometry>
				<sphere radius="0.08"></sphere>
			</geometry>
			<origin xyz="0 0.00 0.00" rpy="0 0 0"></origin>
		</collision>
		<collision>
			<geometry>
				<sphere radius="0.08"></sphere>
			</geometry>
			<origin xyz="0 0.00 -0.02" rpy="0 0 0"></origin>
		</collision> -->

	</link>
	<link name="iiwa_link_7">
		<inertial>
			<origin rpy="0 0 0" xyz="0 0 0.02"></origin>
			<mass value="0.3"></mass>
			<inertia ixx="0.001" ixy="0" ixz="0" iyy="0.001" iyz="0" izz="0.001"></inertia>
		</inertial>
		<visual>
			<origin rpy="0 0 0" xyz="0 0 0"></origin>
			<geometry>
				<mesh filename="link_7.stl"></mesh>
			</geometry>
			<material name="Grey"></material>
		</visual>
		<!-- <collision>
			<geometry>
				<mesh filename="link_7.stl"></mesh>
			</geometry>
		</collision> -->

		<!-- <collision>
			<geometry>
				<sphere radius="0.058129"></sphere>
			</geometry>
			<origin xyz="0 0 0.1" rpy="0 0 0"></origin>
		</collision> -->
	</link>
	<link name="iiwa_link_ee"></link>
	<link name="robotiq_arg2f_base_link">
		<inertial>
			<origin rpy="0 0 0" xyz="8.625E-08 -4.6583E-06 0.03145"></origin>
			<mass value="0.22652"></mass>
			<inertia ixx="0.00020005" ixy="-4.2442E-10" ixz="-2.9069E-10" iyy="0.00017832" iyz="-3.4402E-08" izz="0.00013478"></inertia>
		</inertial>
		<visual>
			<origin rpy="0 0 0" xyz="0 0 0"></origin>
			<geometry>
				<mesh filename="robotiq_arg2f_85_base_link.stl" scale="0.001 0.001 0.001"></mesh>
			</geometry>
			<material name="">
				<color rgba="0.1 0.1 0.1 1"></color>
			</material>
		</visual>
		<collision>
			<geometry>
				<sphere radius="0.053503"></sphere>
			</geometry>
			<origin xyz="-1e-06 -1e-06 0.03976211301029474" rpy="0 0 0"></origin>
		</collision>
	</link>
	<link name="left_outer_knuckle">
		<visual>
			<origin rpy="0 0 0" xyz="0 0 0"></origin>
			<geometry>
				<mesh filename="robotiq_arg2f_85_outer_knuckle.stl" scale="0.001 0.001 0.001"></mesh>
			</geometry>
			<material name="">
				<color rgba="0.792156862745098 0.819607843137255 0.933333333333333 1"></color>
			</material>
		</visual>
		<collision>
			<geometry>
				<sphere radius="0.010984"></sphere>
			</geometry>
			<origin xyz="1e-06 0.000614150337219239 0.0019120895633697507" rpy="0 0 0"></origin>
		</collision>
		<collision>
			<geometry>
				<sphere radius="0.012432"></sphere>
			</geometry>
			<origin xyz="0.0 -0.005664849662780761 0.02519308956336975" rpy="0 0 0"></origin>
		</collision>
		<collision>
			<geometry>
				<sphere radius="0.012226"></sphere>
			</geometry>
			<origin xyz="0.0 -0.0011238496627807612 0.030192089563369752" rpy="0 0 0"></origin>
		</collision>
		<collision>
			<geometry>
				<sphere radius="0.01123"></sphere>
			</geometry>
			<origin xyz="0.0 -0.0003988496627807612 0.02566108956336975" rpy="0 0 0"></origin>
		</collision>
		<collision>
			<geometry>
				<sphere radius="0.007303"></sphere>
			</geometry>
			<origin xyz="0.0 0.0018341503372192387 0.01490708956336975" rpy="0 0 0"></origin>
		</collision>
	</link>
	<link name="left_outer_finger">
		<visual>
			<origin rpy="0 0 0" xyz="0 0 0"></origin>
			<geometry>
				<mesh filename="robotiq_arg2f_85_outer_finger.stl" scale="0.001 0.001 0.001"></mesh>
			</geometry>
			<material name="">
				<color rgba="0.1 0.1 0.1 1"></color>
			</material>
		</visual>
		<collision>
			<geometry>
				<sphere radius="0.011497"></sphere>
			</geometry>
			<origin xyz="0.00488 0.0015613899745941162 0.012645469244003296" rpy="0 0 0"></origin>
		</collision>
		<collision>
			<geometry>
				<sphere radius="0.009975"></sphere>
			</geometry>
			<origin xyz="-0.006963 0.0003353899745941161 0.0025874692440032952" rpy="0 0 0"></origin>
		</collision>
		<collision>
			<geometry>
				<sphere radius="0.010015"></sphere>
			</geometry>
			<origin xyz="0.008541 0.005245389974594116 0.04569646924400329" rpy="0 0 0"></origin>
		</collision>
		<collision>
			<geometry>
				<sphere radius="0.009339"></sphere>
			</geometry>
			<origin xyz="-0.008399 0.0060863899745941166 0.0465464692440033" rpy="0 0 0"></origin>
		</collision>
		<collision>
			<geometry>
				<sphere radius="0.012389"></sphere>
			</geometry>
			<origin xyz="-0.0059 0.002357389974594116 0.018191469244003295" rpy="0 0 0"></origin>
		</collision>
		<collision>
			<geometry>
				<sphere radius="0.009002"></sphere>
			</geometry>
			<origin xyz="0.007492 1.1389974594116017e-05 0.00020946924400329706" rpy="0 0 0"></origin>
		</collision>
		<collision>
			<geometry>
				<sphere radius="0.011071"></sphere>
			</geometry>
			<origin xyz="-0.007347 0.005145389974594116 0.035527469244003296" rpy="0 0 0"></origin>
		</collision>
		<collision>
			<geometry>
				<sphere radius="0.012221"></sphere>
			</geometry>
			<origin xyz="0.006071 0.0036073899745941163 0.028692469244003295" rpy="0 0 0"></origin>
		</collision>
	</link>
	<link name="left_inner_finger">
		<visual>
			<origin rpy="0 0 0" xyz="0 0 0"></origin>
			<geometry>
				<mesh filename="robotiq_arg2f_85_inner_finger.stl" scale="0.001 0.001 0.001"></mesh>
			</geometry>
			<material name="">
				<color rgba="0.1 0.1 0.1 1"></color>
			</material>
		</visual>
		<collision>
			<geometry>
				<sphere radius="0.010605"></sphere>
			</geometry>
			<origin xyz="-0.0001333776209228618 -0.00042106541417874337 0.00032326162205500997" rpy="0 0 0"></origin>
		</collision>
		<collision>
			<geometry>
				<sphere radius="0.011577"></sphere>
			</geometry>
			<origin xyz="-0.0005533776209228618 -0.009420065414178743 0.0031652616220550107" rpy="0 0 0"></origin>
		</collision>
		<collision>
			<geometry>
				<sphere radius="0.012473"></sphere>
			</geometry>
			<origin xyz="-0.00017537762092286182 -0.01666706541417874 0.00843226162205501" rpy="0 0 0"></origin>
		</collision>
		<collision>
			<geometry>
				<sphere radius="0.007804"></sphere>
			</geometry>
			<origin xyz="0.0035886223790771382 -0.015428065414178743 0.021855261622055012" rpy="0 0 0"></origin>
		</collision>
		<collision>
			<geometry>
				<sphere radius="0.008723"></sphere>
			</geometry>
			<origin xyz="-0.0041273776209228615 -0.015206065414178743 0.024027261622055013" rpy="0 0 0"></origin>
		</collision>
		<collision>
			<geometry>
				<sphere radius="0.007462"></sphere>
			</geometry>
			<origin xyz="0.0031446223790771383 -0.015192065414178745 0.03323426162205501" rpy="0 0 0"></origin>
		</collision>
		<collision>
			<geometry>
				<sphere radius="0.00765"></sphere>
			</geometry>
			<origin xyz="0.0014236223790771382 -0.015800065414178742 0.04095526162205501" rpy="0 0 0"></origin>
		</collision>
		<collision>
			<geometry>
				<sphere radius="0.008548"></sphere>
			</geometry>
			<origin xyz="-0.003940377620922862 -0.015415065414178742 0.03781926162205501" rpy="0 0 0"></origin>
		</collision>
	</link>
	<link name="left_inner_finger_pad">
		<visual>
			<origin rpy="0 0 0" xyz="0 0 0"></origin>
			<geometry>
				<box size="0.022 0.00635 0.0375"></box>
			</geometry>
			<material name="">
				<color rgba="0.9 0.9 0.9 1"></color>
			</material>
		</visual>
		<collision>
			<geometry>
				<sphere radius="0.010554"></sphere>
			</geometry>
			<origin xyz="-0.003856 0.0 -0.011665" rpy="0 0 0"></origin>
		</collision>
		<collision>
			<geometry>
				<sphere radius="0.010972"></sphere>
			</geometry>
			<origin xyz="0.007289 0.0 -0.00895" rpy="0 0 0"></origin>
		</collision>
		<collision>
			<geometry>
				<sphere radius="0.009151"></sphere>
			</geometry>
			<origin xyz="-0.004375 0.0 0.001145" rpy="0 0 0"></origin>
		</collision>
		<collision>
			<geometry>
				<sphere radius="0.010294"></sphere>
			</geometry>
			<origin xyz="0.006914 0.0 0.009851" rpy="0 0 0"></origin>
		</collision>
		<collision>
			<geometry>
				<sphere radius="0.009632"></sphere>
			</geometry>
			<origin xyz="-0.00422 0.0 0.012748" rpy="0 0 0"></origin>
		</collision>
	</link>
	<link name="left_inner_knuckle">
		<visual>
			<origin rpy="0 0 0" xyz="0 0 0"></origin>
			<geometry>
				<mesh filename="robotiq_arg2f_85_inner_knuckle.stl" scale="0.001 0.001 0.001"></mesh>
			</geometry>
			<material name="">
				<color rgba="0.1 0.1 0.1 1"></color>
			</material>
		</visual>
		<collision>
			<geometry>
				<sphere radius="0.011422"></sphere>
			</geometry>
			<origin xyz="0.01575 0.004236976961135865 0.0022316007404327397" rpy="0 0 0"></origin>
		</collision>
		<collision>
			<geometry>
				<sphere radius="0.009271"></sphere>
			</geometry>
			<origin xyz="0.0145 0.012565976961135865 0.01625060074043274" rpy="0 0 0"></origin>
		</collision>
		<collision>
			<geometry>
				<sphere radius="0.012513"></sphere>
			</geometry>
			<origin xyz="0.009482 0.023362976961135866 0.02738060074043274" rpy="0 0 0"></origin>
		</collision>
		<collision>
			<geometry>
				<sphere radius="0.010628"></sphere>
			</geometry>
			<origin xyz="0.008242 0.03606797696113587 0.04220860074043274" rpy="0 0 0"></origin>
		</collision>
		<collision>
			<geometry>
				<sphere radius="0.01315"></sphere>
			</geometry>
			<origin xyz="-0.008981 0.023662976961135868 0.02784160074043274" rpy="0 0 0"></origin>
		</collision>
		<collision>
			<geometry>
				<sphere radius="0.009999"></sphere>
			</geometry>
			<origin xyz="-0.008288 0.03617997696113587 0.042382600740432735" rpy="0 0 0"></origin>
		</collision>
		<collision>
			<geometry>
				<sphere radius="0.009398"></sphere>
			</geometry>
			<origin xyz="-0.0145 0.014375976961135866 0.01504860074043274" rpy="0 0 0"></origin>
		</collision>
		<collision>
			<geometry>
				<sphere radius="0.011428"></sphere>
			</geometry>
			<origin xyz="-0.01575 0.0018039769611358641 0.00444860074043274" rpy="0 0 0"></origin>
		</collision>
	</link>
	<link name="right_outer_knuckle">
		<visual>
			<origin rpy="0 0 0" xyz="0 0 0"></origin>
			<geometry>
				<mesh filename="robotiq_arg2f_85_outer_knuckle.stl" scale="0.001 0.001 0.001"></mesh>
			</geometry>
			<material name="">
				<color rgba="0.792156862745098 0.819607843137255 0.933333333333333 1"></color>
			</material>
		</visual>
		<collision>
			<geometry>
				<sphere radius="0.010984"></sphere>
			</geometry>
			<origin xyz="1e-06 0.000614150337219239 0.0019120895633697507" rpy="0 0 0"></origin>
		</collision>
		<collision>
			<geometry>
				<sphere radius="0.012432"></sphere>
			</geometry>
			<origin xyz="0.0 -0.005664849662780761 0.02519308956336975" rpy="0 0 0"></origin>
		</collision>
		<collision>
			<geometry>
				<sphere radius="0.012226"></sphere>
			</geometry>
			<origin xyz="0.0 -0.0011238496627807612 0.030192089563369752" rpy="0 0 0"></origin>
		</collision>
		<collision>
			<geometry>
				<sphere radius="0.01123"></sphere>
			</geometry>
			<origin xyz="0.0 -0.0003988496627807612 0.02566108956336975" rpy="0 0 0"></origin>
		</collision>
		<collision>
			<geometry>
				<sphere radius="0.007303"></sphere>
			</geometry>
			<origin xyz="0.0 0.0018341503372192387 0.01490708956336975" rpy="0 0 0"></origin>
		</collision>
	</link>
	<link name="right_outer_finger">
		<visual>
			<origin rpy="0 0 0" xyz="0 0 0"></origin>
			<geometry>
				<mesh filename="robotiq_arg2f_85_outer_finger.stl" scale="0.001 0.001 0.001"></mesh>
			</geometry>
			<material name="">
				<color rgba="0.1 0.1 0.1 1"></color>
			</material>
		</visual>
		<collision>
			<geometry>
				<sphere radius="0.011497"></sphere>
			</geometry>
			<origin xyz="0.00488 0.0015613899745941162 0.012645469244003296" rpy="0 0 0"></origin>
		</collision>
		<collision>
			<geometry>
				<sphere radius="0.009975"></sphere>
			</geometry>
			<origin xyz="-0.006963 0.0003353899745941161 0.0025874692440032952" rpy="0 0 0"></origin>
		</collision>
		<collision>
			<geometry>
				<sphere radius="0.010015"></sphere>
			</geometry>
			<origin xyz="0.008541 0.005245389974594116 0.04569646924400329" rpy="0 0 0"></origin>
		</collision>
		<collision>
			<geometry>
				<sphere radius="0.009339"></sphere>
			</geometry>
			<origin xyz="-0.008399 0.0060863899745941166 0.0465464692440033" rpy="0 0 0"></origin>
		</collision>
		<collision>
			<geometry>
				<sphere radius="0.012389"></sphere>
			</geometry>
			<origin xyz="-0.0059 0.002357389974594116 0.018191469244003295" rpy="0 0 0"></origin>
		</collision>
		<collision>
			<geometry>
				<sphere radius="0.009002"></sphere>
			</geometry>
			<origin xyz="0.007492 1.1389974594116017e-05 0.00020946924400329706" rpy="0 0 0"></origin>
		</collision>
		<collision>
			<geometry>
				<sphere radius="0.011071"></sphere>
			</geometry>
			<origin xyz="-0.007347 0.005145389974594116 0.035527469244003296" rpy="0 0 0"></origin>
		</collision>
		<collision>
			<geometry>
				<sphere radius="0.012221"></sphere>
			</geometry>
			<origin xyz="0.006071 0.0036073899745941163 0.028692469244003295" rpy="0 0 0"></origin>
		</collision>
	</link>
	<link name="right_inner_finger">
		<visual>
			<origin rpy="0 0 0" xyz="0 0 0"></origin>
			<geometry>
				<mesh filename="robotiq_arg2f_85_inner_finger.stl" scale="0.001 0.001 0.001"></mesh>
			</geometry>
			<material name="">
				<color rgba="0.1 0.1 0.1 1"></color>
			</material>
		</visual>
		<collision>
			<geometry>
				<sphere radius="0.010605"></sphere>
			</geometry>
			<origin xyz="-0.0001333776209228618 -0.00042106541417874337 0.00032326162205500997" rpy="0 0 0"></origin>
		</collision>
		<collision>
			<geometry>
				<sphere radius="0.011577"></sphere>
			</geometry>
			<origin xyz="-0.0005533776209228618 -0.009420065414178743 0.0031652616220550107" rpy="0 0 0"></origin>
		</collision>
		<collision>
			<geometry>
				<sphere radius="0.012473"></sphere>
			</geometry>
			<origin xyz="-0.00017537762092286182 -0.01666706541417874 0.00843226162205501" rpy="0 0 0"></origin>
		</collision>
		<collision>
			<geometry>
				<sphere radius="0.007804"></sphere>
			</geometry>
			<origin xyz="0.0035886223790771382 -0.015428065414178743 0.021855261622055012" rpy="0 0 0"></origin>
		</collision>
		<collision>
			<geometry>
				<sphere radius="0.008723"></sphere>
			</geometry>
			<origin xyz="-0.0041273776209228615 -0.015206065414178743 0.024027261622055013" rpy="0 0 0"></origin>
		</collision>
		<collision>
			<geometry>
				<sphere radius="0.007462"></sphere>
			</geometry>
			<origin xyz="0.0031446223790771383 -0.015192065414178745 0.03323426162205501" rpy="0 0 0"></origin>
		</collision>
		<collision>
			<geometry>
				<sphere radius="0.00765"></sphere>
			</geometry>
			<origin xyz="0.0014236223790771382 -0.015800065414178742 0.04095526162205501" rpy="0 0 0"></origin>
		</collision>
		<collision>
			<geometry>
				<sphere radius="0.008548"></sphere>
			</geometry>
			<origin xyz="-0.003940377620922862 -0.015415065414178742 0.03781926162205501" rpy="0 0 0"></origin>
		</collision>
	</link>
	<link name="right_inner_finger_pad">
		<visual>
			<origin rpy="0 0 0" xyz="0 0 0"></origin>
			<geometry>
				<box size="0.022 0.00635 0.0375"></box>
			</geometry>
			<material name="">
				<color rgba="0.9 0.9 0.9 1"></color>
			</material>
		</visual>
		<collision>
			<geometry>
				<sphere radius="0.010554"></sphere>
			</geometry>
			<origin xyz="-0.003856 0.0 -0.011665" rpy="0 0 0"></origin>
		</collision>
		<collision>
			<geometry>
				<sphere radius="0.010972"></sphere>
			</geometry>
			<origin xyz="0.007289 0.0 -0.00895" rpy="0 0 0"></origin>
		</collision>
		<collision>
			<geometry>
				<sphere radius="0.009151"></sphere>
			</geometry>
			<origin xyz="-0.004375 0.0 0.001145" rpy="0 0 0"></origin>
		</collision>
		<collision>
			<geometry>
				<sphere radius="0.010294"></sphere>
			</geometry>
			<origin xyz="0.006914 0.0 0.009851" rpy="0 0 0"></origin>
		</collision>
		<collision>
			<geometry>
				<sphere radius="0.009632"></sphere>
			</geometry>
			<origin xyz="-0.00422 0.0 0.012748" rpy="0 0 0"></origin>
		</collision>
	</link>
	<link name="right_inner_knuckle">
		<visual>
			<origin rpy="0 0 0" xyz="0 0 0"></origin>
			<geometry>
				<mesh filename="robotiq_arg2f_85_inner_knuckle.stl" scale="0.001 0.001 0.001"></mesh>
			</geometry>
			<material name="">
				<color rgba="0.1 0.1 0.1 1"></color>
			</material>
		</visual>
		<collision>
			<geometry>
				<sphere radius="0.011422"></sphere>
			</geometry>
			<origin xyz="0.01575 0.004236976961135865 0.0022316007404327397" rpy="0 0 0"></origin>
		</collision>
		<collision>
			<geometry>
				<sphere radius="0.009271"></sphere>
			</geometry>
			<origin xyz="0.0145 0.012565976961135865 0.01625060074043274" rpy="0 0 0"></origin>
		</collision>
		<collision>
			<geometry>
				<sphere radius="0.012513"></sphere>
			</geometry>
			<origin xyz="0.009482 0.023362976961135866 0.02738060074043274" rpy="0 0 0"></origin>
		</collision>
		<collision>
			<geometry>
				<sphere radius="0.010628"></sphere>
			</geometry>
			<origin xyz="0.008242 0.03606797696113587 0.04220860074043274" rpy="0 0 0"></origin>
		</collision>
		<collision>
			<geometry>
				<sphere radius="0.01315"></sphere>
			</geometry>
			<origin xyz="-0.008981 0.023662976961135868 0.02784160074043274" rpy="0 0 0"></origin>
		</collision>
		<collision>
			<geometry>
				<sphere radius="0.009999"></sphere>
			</geometry>
			<origin xyz="-0.008288 0.03617997696113587 0.042382600740432735" rpy="0 0 0"></origin>
		</collision>
		<collision>
			<geometry>
				<sphere radius="0.009398"></sphere>
			</geometry>
			<origin xyz="-0.0145 0.014375976961135866 0.01504860074043274" rpy="0 0 0"></origin>
		</collision>
		<collision>
			<geometry>
				<sphere radius="0.011428"></sphere>
			</geometry>
			<origin xyz="-0.01575 0.0018039769611358641 0.00444860074043274" rpy="0 0 0"></origin>
		</collision>
	</link>
	<joint name="world_iiwa_joint" type="fixed">
		<origin rpy="0 0 0" xyz="0 0 0"></origin>
		<parent link="world"></parent>
		<child link="iiwa_link_0"></child>
	</joint>
	<joint name="iiwa_joint_1" type="revolute">
		<parent link="iiwa_link_0"></parent>
		<child link="iiwa_link_1"></child>
		<origin rpy="0 0 0" xyz="0 0 0.1575"></origin>
		<axis xyz="0 0 1"></axis>
		<limit effort="300" lower="-2.96705972839" upper="2.96705972839" velocity="10"></limit>
		<safety_controller k_position="100" k_velocity="2" soft_lower_limit="-2.93215314335" soft_upper_limit="2.93215314335"></safety_controller>
		<dynamics damping="0.5"></dynamics>
	</joint>
	<joint name="iiwa_joint_2" type="revolute">
		<parent link="iiwa_link_1"></parent>
		<child link="iiwa_link_2"></child>
		<origin rpy="1.57079632679   0 3.14159265359" xyz="0 0 0.2025"></origin>
		<axis xyz="0 0 1"></axis>
		<limit effort="300" lower="-2.09439510239" upper="2.09439510239" velocity="10"></limit>
		<safety_controller k_position="100" k_velocity="2" soft_lower_limit="-2.05948851735" soft_upper_limit="2.05948851735"></safety_controller>
		<dynamics damping="0.5"></dynamics>
	</joint>
	<joint name="iiwa_joint_3" type="revolute">
		<parent link="iiwa_link_2"></parent>
		<child link="iiwa_link_3"></child>
		<origin rpy="1.57079632679 0 3.14159265359" xyz="0 0.2045 0"></origin>
		<axis xyz="0 0 1"></axis>
		<limit effort="300" lower="-2.96705972839" upper="2.96705972839" velocity="10"></limit>
		<safety_controller k_position="100" k_velocity="2" soft_lower_limit="-2.93215314335" soft_upper_limit="2.93215314335"></safety_controller>
		<dynamics damping="0.5"></dynamics>
	</joint>
	<joint name="iiwa_joint_4" type="revolute">
		<parent link="iiwa_link_3"></parent>
		<child link="iiwa_link_4"></child>
		<origin rpy="1.57079632679 0 0" xyz="0 0 0.2155"></origin>
		<axis xyz="0 0 1"></axis>
		<limit effort="300" lower="-2.09439510239" upper="2.09439510239" velocity="10"></limit>
		<safety_controller k_position="100" k_velocity="2" soft_lower_limit="-2.05948851735" soft_upper_limit="2.05948851735"></safety_controller>
		<dynamics damping="0.5"></dynamics>
	</joint>
	<joint name="iiwa_joint_5" type="revolute">
		<parent link="iiwa_link_4"></parent>
		<child link="iiwa_link_5"></child>
		<origin rpy="-1.57079632679 3.14159265359 0" xyz="0 0.1845 0"></origin>
		<axis xyz="0 0 1"></axis>
		<limit effort="300" lower="-2.96705972839" upper="2.96705972839" velocity="10"></limit>
		<safety_controller k_position="100" k_velocity="2" soft_lower_limit="-2.93215314335" soft_upper_limit="2.93215314335"></safety_controller>
		<dynamics damping="0.5"></dynamics>
	</joint>
	<joint name="iiwa_joint_6" type="revolute">
		<parent link="iiwa_link_5"></parent>
		<child link="iiwa_link_6"></child>
		<origin rpy="1.57079632679 0 0" xyz="0 0 0.2155"></origin>
		<axis xyz="0 0 1"></axis>
		<limit effort="300" lower="-2.09439510239" upper="2.09439510239" velocity="10"></limit>
		<safety_controller k_position="100" k_velocity="2" soft_lower_limit="-2.05948851735" soft_upper_limit="2.05948851735"></safety_controller>
		<dynamics damping="0.5"></dynamics>
	</joint>
	<joint name="iiwa_joint_7" type="revolute">
		<parent link="iiwa_link_6"></parent>
		<child link="iiwa_link_7"></child>
		<origin rpy="-1.57079632679 3.14159265359 0" xyz="0 0.081 0"></origin>
		<axis xyz="0 0 1"></axis>
		<limit effort="300" lower="-3.05432619099" upper="3.05432619099" velocity="10"></limit>
		<safety_controller k_position="100" k_velocity="2" soft_lower_limit="-3.01941960595" soft_upper_limit="3.01941960595"></safety_controller>
		<dynamics damping="0.5"></dynamics>
	</joint>
	<joint name="iiwa_joint_ee" type="fixed">
		<parent link="iiwa_link_7"></parent>
		<child link="iiwa_link_ee"></child>
		<origin rpy="0 0 0" xyz="0 0 0.045"></origin>
	</joint>
	<joint name="iiwa_robotiq_mount" type="fixed">
		<parent link="iiwa_link_ee"></parent>
		<child link="robotiq_arg2f_base_link"></child>
		<origin rpy="0 0 0" xyz="0 0 0"></origin>
	</joint>
	<joint name="finger_joint" type="fixed">
		<origin rpy="0 0 3.141592653589793" xyz="0 -0.0306011 0.054904"></origin>
		<parent link="robotiq_arg2f_base_link"></parent>
		<child link="left_outer_knuckle"></child>
	</joint>
	<joint name="left_outer_finger_joint" type="fixed">
		<origin rpy="0 0 0" xyz="0 0.0315 -0.0041"></origin>
		<parent link="left_outer_knuckle"></parent>
		<child link="left_outer_finger"></child>
	</joint>
	<joint name="left_inner_knuckle_joint" type="fixed">
		<origin rpy="0 0 3.141592653589793" xyz="0 -0.0127 0.06142"></origin>
		<parent link="robotiq_arg2f_base_link"></parent>
		<child link="left_inner_knuckle"></child>
	</joint>
	<joint name="left_inner_finger_joint" type="fixed">
		<origin rpy="0 0 0" xyz="0 0.0061 0.0471"></origin>
		<parent link="left_outer_finger"></parent>
		<child link="left_inner_finger"></child>
	</joint>
	<joint name="left_inner_finger_pad_joint" type="fixed">
		<origin rpy="0 0 0" xyz="0 -0.0220203446692936 0.03242"></origin>
		<parent link="left_inner_finger"></parent>
		<child link="left_inner_finger_pad"></child>
	</joint>
	<joint name="right_outer_knuckle_joint" type="fixed">
		<origin rpy="0 0 0" xyz="0 0.0306011 0.054904"></origin>
		<parent link="robotiq_arg2f_base_link"></parent>
		<child link="right_outer_knuckle"></child>
	</joint>
	<joint name="right_outer_finger_joint" type="fixed">
		<origin rpy="0 0 0" xyz="0 0.0315 -0.0041"></origin>
		<parent link="right_outer_knuckle"></parent>
		<child link="right_outer_finger"></child>
	</joint>
	<joint name="right_inner_knuckle_joint" type="fixed">
		<origin rpy="0 0 0.0" xyz="0 0.0127 0.06142"></origin>
		<parent link="robotiq_arg2f_base_link"></parent>
		<child link="right_inner_knuckle"></child>
	</joint>
	<joint name="right_inner_finger_joint" type="fixed">
		<origin rpy="0 0 0" xyz="0 0.0061 0.0471"></origin>
		<parent link="right_outer_finger"></parent>
		<child link="right_inner_finger"></child>
	</joint>
	<joint name="right_inner_finger_pad_joint" type="fixed">
		<origin rpy="0 0 0" xyz="0 -0.0220203446692936 0.03242"></origin>
		<parent link="right_inner_finger"></parent>
		<child link="right_inner_finger_pad"></child>
	</joint>
	<gazebo reference="iiwa_joint_7">
		<provideFeedback>true</provideFeedback>
	</gazebo>
	<gazebo>
		<plugin filename="libgazebo_ros_ft_sensor.so" name="ft_sensor">
			<updateRate>50.0</updateRate>
			<topicName>/iiwa/state/CartesianWrench</topicName>
			<jointName>iiwa_joint_7</jointName>
		</plugin>
	</gazebo>
	<gazebo>
		<plugin filename="libgazebo_ros_control.so" name="gazebo_ros_control">
			<robotNamespace>/iiwa</robotNamespace>
		</plugin>
	</gazebo>
	<gazebo reference="iiwa_link_0">
		<material>Gazebo/Grey</material>
		<mu1>0.2</mu1>
		<mu2>0.2</mu2>
	</gazebo>
	<gazebo reference="iiwa_link_1">
		<material>Gazebo/Orange</material>
		<mu1>0.2</mu1>
		<mu2>0.2</mu2>
	</gazebo>
	<gazebo reference="iiwa_link_2">
		<material>Gazebo/Orange</material>
		<mu1>0.2</mu1>
		<mu2>0.2</mu2>
	</gazebo>
	<gazebo reference="iiwa_link_3">
		<material>Gazebo/Orange</material>
		<mu1>0.2</mu1>
		<mu2>0.2</mu2>
	</gazebo>
	<gazebo reference="iiwa_link_4">
		<material>Gazebo/Orange</material>
		<mu1>0.2</mu1>
		<mu2>0.2</mu2>
	</gazebo>
	<gazebo reference="iiwa_link_5">
		<material>Gazebo/Orange</material>
		<mu1>0.2</mu1>
		<mu2>0.2</mu2>
	</gazebo>
	<gazebo reference="iiwa_link_6">
		<material>Gazebo/Orange</material>
		<mu1>0.2</mu1>
		<mu2>0.2</mu2>
	</gazebo>
	<gazebo reference="iiwa_link_7">
		<material>Gazebo/Grey</material>
		<mu1>0.2</mu1>
		<mu2>0.2</mu2>
	</gazebo>
	<transmission name="iiwa_tran_1">
		<robotNamespace>/iiwa</robotNamespace>
		<type>transmission_interface/SimpleTransmission</type>
		<joint name="iiwa_joint_1">
			<hardwareInterface>hardware_interface/PositionJointInterface</hardwareInterface>
		</joint>
		<actuator name="iiwa_motor_1">
			<hardwareInterface>hardware_interface/PositionJointInterface</hardwareInterface>
			<mechanicalReduction>1</mechanicalReduction>
		</actuator>
	</transmission>
	<transmission name="iiwa_tran_2">
		<robotNamespace>/iiwa</robotNamespace>
		<type>transmission_interface/SimpleTransmission</type>
		<joint name="iiwa_joint_2">
			<hardwareInterface>hardware_interface/PositionJointInterface</hardwareInterface>
		</joint>
		<actuator name="iiwa_motor_2">
			<hardwareInterface>hardware_interface/PositionJointInterface</hardwareInterface>
			<mechanicalReduction>1</mechanicalReduction>
		</actuator>
	</transmission>
	<transmission name="iiwa_tran_3">
		<robotNamespace>/iiwa</robotNamespace>
		<type>transmission_interface/SimpleTransmission</type>
		<joint name="iiwa_joint_3">
			<hardwareInterface>hardware_interface/PositionJointInterface</hardwareInterface>
		</joint>
		<actuator name="iiwa_motor_3">
			<hardwareInterface>hardware_interface/PositionJointInterface</hardwareInterface>
			<mechanicalReduction>1</mechanicalReduction>
		</actuator>
	</transmission>
	<transmission name="iiwa_tran_4">
		<robotNamespace>/iiwa</robotNamespace>
		<type>transmission_interface/SimpleTransmission</type>
		<joint name="iiwa_joint_4">
			<hardwareInterface>hardware_interface/PositionJointInterface</hardwareInterface>
		</joint>
		<actuator name="iiwa_motor_4">
			<hardwareInterface>hardware_interface/PositionJointInterface</hardwareInterface>
			<mechanicalReduction>1</mechanicalReduction>
		</actuator>
	</transmission>
	<transmission name="iiwa_tran_5">
		<robotNamespace>/iiwa</robotNamespace>
		<type>transmission_interface/SimpleTransmission</type>
		<joint name="iiwa_joint_5">
			<hardwareInterface>hardware_interface/PositionJointInterface</hardwareInterface>
		</joint>
		<actuator name="iiwa_motor_5">
			<hardwareInterface>hardware_interface/PositionJointInterface</hardwareInterface>
			<mechanicalReduction>1</mechanicalReduction>
		</actuator>
	</transmission>
	<transmission name="iiwa_tran_6">
		<robotNamespace>/iiwa</robotNamespace>
		<type>transmission_interface/SimpleTransmission</type>
		<joint name="iiwa_joint_6">
			<hardwareInterface>hardware_interface/PositionJointInterface</hardwareInterface>
		</joint>
		<actuator name="iiwa_motor_6">
			<hardwareInterface>hardware_interface/PositionJointInterface</hardwareInterface>
			<mechanicalReduction>1</mechanicalReduction>
		</actuator>
	</transmission>
	<transmission name="iiwa_tran_7">
		<robotNamespace>/iiwa</robotNamespace>
		<type>transmission_interface/SimpleTransmission</type>
		<joint name="iiwa_joint_7">
			<hardwareInterface>hardware_interface/PositionJointInterface</hardwareInterface>
		</joint>
		<actuator name="iiwa_motor_7">
			<hardwareInterface>hardware_interface/PositionJointInterface</hardwareInterface>
			<mechanicalReduction>1</mechanicalReduction>
		</actuator>
	</transmission>
</robot>